Workbook
Name Slicer_Department: #N/A
Name Slicer_Region: #N/A

Sheet Sheet1

Sheet Data Entry
A1: Serial No. | B1: Name | C1: Jan | D1: Feb | E1: March | F1: Total | G1: Total | H1: Total | I1: Average | J1: Maximum | K1: Minimum
A2: 1 | B2: A | C2: 500 | D2: 100 | E2: 100 | F2: =C2+D2+E2 -> 700 | G2: =SUM(C2,D2,E2) -> 700 | H2: =SUM(C2:E2) -> 700 | I2: =AVERAGE(C2:E2) -> 233.33333 | J2: =MAX(C2:E2) -> 500 | K2: =MIN(C2:E2) -> 100
A3: 2 | B3: B | C3: 200 | D3: 200 | E3: 200 | F3: =C3+D3+E3 -> 600 | G3: =SUM(C3,D3,E3) -> 600 | H3: =SUM(C3:E3) -> 600 | I3: =AVERAGE(C3:E3) -> 200 | J3: =MAX(C3:E3) -> 200 | K3: =MIN(C3:E3) -> 200
A4: 3 | B4: C | C4: 300 | D4: 300 | E4: 300 | F4: =C4+D4+E4 -> 900 | G4: =SUM(C4,D4,E4) -> 900 | H4: =SUM(C4:E4) -> 900 | I4: =AVERAGE(C4:E4) -> 300 | J4: =MAX(C4:E4) -> 300 | K4: =MIN(C4:E4) -> 300
A5: 4 | B5: D | C5: 400 | D5: 400 | E5: 400 | F5: =C5+D5+E5 -> 1200 | G5: =SUM(C5,D5,E5) -> 1200 | H5: =SUM(C5:E5) -> 1200 | I5: =AVERAGE(C5:E5) -> 400 | J5: =MAX(C5:E5) -> 400 | K5: =MIN(C5:E5) -> 400
A6: 5 | B6: E | C6: 500 | D6: 500 | E6: 500 | F6: =C6+D6+E6 -> 1500 | G6: =SUM(C6,D6,E6) -> 1500 | H6: =SUM(C6:E6) -> 1500 | I6: =AVERAGE(C6:E6) -> 500 | J6: =MAX(C6:E6) -> 500 | K6: =MIN(C6:E6) -> 500
A7: 6 | B7: F | C7: 600 | D7: 600 | E7: 600 | F7: =C7+D7+E7 -> 1800 | G7: =SUM(C7,D7,E7) -> 1800 | H7: =SUM(C7:E7) -> 1800 | I7: =AVERAGE(C7:E7) -> 600 | J7: =MAX(C7:E7) -> 600 | K7: =MIN(C7:E7) -> 600
A8: 7 | B8: G | C8: 700 | D8: 700 | E8: 700 | F8: =C8+D8+E8 -> 2100 | G8: =SUM(C8,D8,E8) -> 2100 | H8: =SUM(C8:E8) -> 2100 | I8: =AVERAGE(C8:E8) -> 700 | J8: =MAX(C8:E8) -> 700 | K8: =MIN(C8:E8) -> 700
A9: 8 | B9: H | C9: 800 | D9: 800 | E9: 800 | F9: =C9+D9+E9 -> 2400 | G9: =SUM(C9,D9,E9) -> 2400 | H9: =SUM(C9:E9) -> 2400 | I9: =AVERAGE(C9:E9) -> 800 | J9: =MAX(C9:E9) -> 800 | K9: =MIN(C9:E9) -> 800
A10: 9 | B10: I | C10: 900 | D10: 900 | E10: 900 | F10: =C10+D10+E10 -> 2700 | G10: =SUM(C10,D10,E10) -> 2700 | H10: =SUM(C10:E10) -> 2700 | I10: =AVERAGE(C10:E10) -> 900 | J10: =MAX(C10:E10) -> 900 | K10: =MIN(C10:E10) -> 900
A11: 10 | B11: J | C11: 1000 | D11: 1000 | E11: 1000 | F11: =C11+D11+E11 -> 3000 | G11: =SUM(C11,D11,E11) -> 3000 | H11: =SUM(C11:E11) -> 3000 | I11: =AVERAGE(C11:E11) -> 1000 | J11: =MAX(C11:E11) -> 1000 | K11: =MIN(C11:E11) -> 1000
C12: =SUM(C2:C11) -> 5900 | D12: =SUM(D2:D11) -> 5500 | E12: =SUM(E2:E11) -> 5500 | G12: =SUM(G2:G11) -> 16900
B18: 46113 | C18: dd-mm-yyyy
B20: 46113 | C20: dd-mmm-yyyy
C33: 3643335
C36: 97643453
C37: =D37 -> 31435135 | D37: 31435135
C43: 500 | D43: 400 | E43: =500-200 -> 300 | F43: =C43-D43 -> 100
C45: 500 | D45: 50 | E45: =C45*D45 -> 25000 | F45: =PRODUCT(C45:D45) -> 25000
C47: 50000 | D47: 50 | E47: =C47/D47 -> 1000

Sheet Arthmatic
A1: Student Name | B1: Hindi | C1: English | D1: Maths | E1: Science | F1: Count | G1: Counta | H1: Countblank
A2: A | B2: ab | C2: 40 | D2: 72 | F2: =COUNT(B2:E2) -> 2 | G2: =COUNTA(B2:E2) -> 3 | H2: =COUNTBLANK(B2:E2) -> 1
A3: B | B3: ab | C3: 44 | D3: 71 | E3: ab | F3: =COUNT(B3:E3) -> 2 | G3: =COUNTA(B3:E3) -> 4 | H3: =COUNTBLANK(B3:E3) -> 0
A4: C | B4: 14 | D4: 40 | E4: 85 | F4: =COUNT(B4:E4) -> 3 | G4: =COUNTA(B4:E4) -> 3 | H4: =COUNTBLANK(B4:E4) -> 1
A5: D | B5: 84 | C5: 47 | D5: 67 | E5: 59 | F5: =COUNT(B5:E5) -> 4 | G5: =COUNTA(B5:E5) -> 4 | H5: =COUNTBLANK(B5:E5) -> 0
A6: E | B6: 5 | C6: 87 | E6: ab | F6: =COUNT(B6:E6) -> 2 | G6: =COUNTA(B6:E6) -> 3 | H6: =COUNTBLANK(B6:E6) -> 1
A7: F | B7: ab | C7: 33 | D7: 39 | E7: 13 | F7: =COUNT(B7:E7) -> 3 | G7: =COUNTA(B7:E7) -> 4 | H7: =COUNTBLANK(B7:E7) -> 0
A8: G | B8: 4 | C8: 59 | E8: 43 | F8: =COUNT(B8:E8) -> 3 | G8: =COUNTA(B8:E8) -> 3 | H8: =COUNTBLANK(B8:E8) -> 1
A9: H | B9: 79 | E9: 86 | F9: =COUNT(B9:E9) -> 2 | G9: =COUNTA(B9:E9) -> 2 | H9: =COUNTBLANK(B9:E9) -> 2
A10: I | B10: 65 | C10: 50 | D10: ab | E10: 90 | F10: =COUNT(B10:E10) -> 3 | G10: =COUNTA(B10:E10) -> 4 | H10: =COUNTBLANK(B10:E10) -> 0
A11: J | C11: 76 | D11: 85 | F11: =COUNT(B11:E11) -> 2 | G11: =COUNTA(B11:E11) -> 2 | H11: =COUNTBLANK(B11:E11) -> 2

Sheet Conditional Formatting
A1: Date | B1: Employee Name | C1: Department | D1: Region | E1: Sales (₹) | F1: Target (₹)
A2: 46096 | B2: Amit Sharma | C2: Finance | D2: East | E2: 78805 | F2: 47568
A3: 46097 | B3: Neha Verma | C3: Sales | D3: South | E3: 81218 | F3: 71354
A4: 46098 | B4: Rohit Gupta | C4: Marketing | D4: South | E4: 36687 | F4: 56505
A5: 46099 | B5: Simran Kaur | C5: Finance | D5: South | E5: 20000 | F5: 50614
A6: 46100 | B6: Vikas Jain | C6: Finance | D6: North | E6: 89634 | F6: 79176
A7: 46101 | B7: Priya Mehta | C7: Marketing | D7: South | E7: 62015 | F7: 69434
A8: 46102 | B8: Karan Malhotra | C8: Marketing | D8: East | E8: 20000 | F8: 69434
A9: 46103 | B9: Anjali Singh | C9: Finance | D9: West | E9: 20000 | F9: 60910
A10: 46104 | B10: Rahul Kapoor | C10: Sales | D10: West | E10: 70837 | F10: 85222
A11: 46111 | B11: Sneha Reddy | C11: Finance | D11: West | E11: 52700 | F11: 85222
A12: 46112 | B12: Manish Yadav | C12: Sales | D12: North | E12: 44811 | F12: 65279
A13: 46113 | B13: Pooja Bansal | C13: Marketing | D13: South | E13: 50833 | F13: 48220
... A31: 46131 | B31: Payal Singh | C31: Sales | D31: East | E31: 84534 | F31: 74049
A34: Date | B34: Employee Name | C34: Department | D34: Region | E34: Sales (₹) | F34: Target (₹) | G34: Target (₹)
A35: 46096 | B35: Amit Sharma | C35: Finance | D35: East | E35: 78805 | F35: 47568 | G35: 47568
A36: 46097 | B36: Neha Verma | C36: Sales | D36: South | E36: 81218 | F36: 71354 | G36: 71354
A37: 46098 | B37: Rohit Gupta | C37: Marketing | D37: South | E37: 36687 | F37: 56505 | G37: 56505
A38: 46099 | B38: Simran Kaur | C38: Finance | D38: South | E38: 20000 | F38: 50614 | G38: 50614
A39: 46100 | B39: Vikas Jain | C39: Finance | D39: North | E39: 89634 | F39: 79176 | G39: 79176
A40: 46101 | B40: Priya Mehta | C40: Marketing | D40: South | E40: 62015 | F40: 69434 | G40: 69434
A41: 46102 | B41: Karan Malhotra | C41: Marketing | D41: East | E41: 20000 | F41: 69434 | G41: 69434
A42: 46103 | B42: Anjali Singh | C42: Finance | D42: West | E42: 20000 | F42: 60910 | G42: 60910
A43: 46104 | B43: Rahul Kapoor | C43: Sales | D43: West | E43: 70837 | F43: 85222 | G43: 85222
A44: 46111 | B44: Sneha Reddy | C44: Finance | D44: West | E44: 52700 | F44: 85222 | G44: 85222
A45: 46112 | B45: Manish Yadav | C45: Sales | D45: North | E45: 44811 | F45: 65279 | G45: 65279
A46: 46113 | B46: Pooja Bansal | C46: Marketing | D46: South | E46: 50833 | F46: 48220 | G46: 48220
... A64: 46131 | B64: Payal Singh | C64: Sales | D64: East | E64: 84534 | F64: 74049 | G64: 74049
A70: Date | B70: Employee Name | C70: Department | D70: Region | E70: Sales (₹) | F70: Target (₹) | G70: Target (₹)
A71: 46096 | B71: Amit Sharma | C71: Finance | D71: East | E71: 78805 | F71: 47568 | G71: 47568
A72: 46097 | B72: Neha Verma | C72: Sales | D72: South | E72: 81218 | F72: 71354 | G72: 71354
A73: 46098 | B73: Rohit Gupta | C73: Marketing | D73: South | E73: 36687 | F73: 56505 | G73: 56505
A74: 46099 | B74: Simran Kaur | C74: Finance | D74: South | E74: 20000 | F74: 50614 | G74: 50614
A75: 46100 | B75: Vikas Jain | C75: Finance | D75: North | E75: 89634 | F75: 79176 | G75: 79176
A76: 46101 | B76: Priya Mehta | C76: Marketing | D76: South | E76: 62015 | F76: 69434 | G76: 69434
A77: 46102 | B77: Karan Malhotra | C77: Marketing | D77: East | E77: 20000 | F77: 69434 | G77: 69434
A78: 46103 | B78: Anjali Singh | C78: Finance | D78: West | E78: 20000 | F78: 60910 | G78: 60910
A79: 46104 | B79: Rahul Kapoor | C79: Sales | D79: West | E79: 70837 | F79: 85222 | G79: 85222
A80: 46111 | B80: Sneha Reddy | C80: Finance | D80: West | E80: 52700 | F80: 85222 | G80: 85222
A81: 46112 | B81: Manish Yadav | C81: Sales | D81: North | E81: 44811 | F81: 65279 | G81: 65279
...

Sheet Find , Replace
A1: Date | B1: Employee Name | C1: Department | D1: Region | E1: Sales (₹) | F1: Target (₹) | G1: Target (₹)
A2: 46096 | B2: Amit Sharma | C2: Finance | D2: East | E2: 78805 | F2: 47568 | G2: 47568
A3: 46097 | B3: Amit Verma | C3: Sales | D3: South | E3: 81218 | F3: 71354 | G3: 71354
A4: 46098 | B4: Rohit Gupta | C4: Marketing | D4: South | E4: 36687 | F4: 56505 | G4: 56505
A5: 46099 | B5: Simran Kaur | C5: Finance | D5: South | E5: 20000 | F5: 50614 | G5: 50614
A6: 46100 | B6: Vikas Jain | C6: Finance | D6: North | E6: 89634 | F6: 79176 | G6: 79176
A7: 46101 | B7: Priya Mehta | C7: Marketing | D7: South | E7: 62015 | F7: 69434 | G7: 69434
A8: 46102 | B8: Karan Malhotra | C8: Marketing | D8: East | E8: 20000 | F8: 69434 | G8: 69434
A9: 46103 | B9: Anjali Singh | C9: Finance | D9: West | E9: 20000 | F9: 60910 | G9: 60910
A10: 46104 | B10: Rahul Kapoor | C10: Sales | D10: West | E10: 70837 | F10: 85222 | G10: 85222
A11: 46111 | B11: Sneha Reddy | C11: Finance | D11: West | E11: 52700 | F11: 85222 | G11: 85222
A12: 46112 | B12: Manish Yadav | C12: Sales | D12: North | E12: 44811 | F12: 65279 | G12: 65279
A13: 46113 | B13: Pooja Bansal | C13: Marketing | D13: South | E13: 50833 | F13: 48220 | G13: 48220
... A31: 46131 | B31: Payal Singh | C31: Sales | D31: East | E31: 84534 | F31: 74049 | G31: 74049

Sheet CleaR
I1: Date | J1: Employee Name | K1: Department | L1: Region | M1: Sales (₹) | N1: Target (₹) | O1: Target (₹)
I2: 46096 | J2: Amit Sharma | K2: Finance | L2: East | M2: 78805 | N2: 47568 | O2: 47568
I3: 46097 | J3: Amit Verma | K3: Sales | L3: South | M3: 81218 | N3: 71354 | O3: 71354
I4: 46098 | J4: Rohit Gupta | K4: Marketing | L4: South | M4: 36687 | N4: 56505 | O4: 56505
I5: 46099 | J5: Simran Kaur | K5: Finance | L5: South | M5: 20000 | N5: 50614 | O5: 50614
I6: 46100 | J6: Vikas Jain | K6: Finance | L6: North | M6: 89634 | N6: 79176 | O6: 79176
I7: 46101 | J7: Priya Mehta | K7: Marketing | L7: South | M7: 62015 | N7: 69434 | O7: 69434
I8: 46102 | J8: Karan Malhotra | K8: Marketing | L8: East | M8: 20000 | N8: 69434 | O8: 69434
I9: 46103 | J9: Anjali Singh | K9: Finance | L9: West | M9: 20000 | N9: 60910 | O9: 60910
I10: 46104 | J10: Rahul Kapoor | K10: Sales | L10: West | M10: 70837 | N10: 85222 | O10: 85222
I11: 46111 | J11: Sneha Reddy | K11: Finance | L11: West | M11: 52700 | N11: 85222 | O11: 85222
I12: 46112 | J12: Manish Yadav | K12: Sales | L12: North | M12: 44811 | N12: 65279 | O12: 65279
I13: 46113 | J13: Pooja Bansal | K13: Marketing | L13: South | M13: 50833 | N13: 48220 | O13: 48220
... I31: 46131 | J31: Payal Singh | K31: Sales | L31: East | M31: 84534 | N31: 74049 | O31: 74049
A36: Date | B36: Employee Name | C36: Department | D36: Region | E36: Sales (₹) | F36: Target (₹) | G36: Target (₹) | I36: Date | J36: Employee Name | K36: Department | L36: Region | M36: Sales (₹) | N36: Target (₹) | O36: Target (₹) | Q36: Date | R36: Employee Name | S36: Department | T36: Region | U36: Sales (₹) | V36: Target (₹) | W36: Target (₹)
A37: 46096 | B37: Amit Sharma | C37: Finance | D37: East | E37: 78805 | F37: 47568 | G37: 47568 | I37: 46096 | J37: Amit Sharma | K37: Finance | L37: East | M37: 78805 | N37: 47568 | O37: 47568 | Q37: 46096 | R37: Amit Sharma | S37: Finance | T37: East | U37: 78805 | V37: 47568 | W37: 47568
A38: 46097 | B38: Amit Verma | C38: Sales | D38: South | E38: 81218 | F38: 71354 | G38: 71354 | I38: 46097 | J38: Amit Verma | K38: Sales | L38: South | M38: 81218 | N38: 71354 | O38: 71354 | Q38: 46097 | R38: Amit Verma | S38: Sales | T38: South | U38: 81218 | V38: 71354 | W38: 71354
A39: 46098 | B39: Rohit Gupta | C39: Marketing | D39: South | E39: 36687 | F39: 56505 | G39: 56505 | I39: 46098 | J39: Rohit Gupta | K39: Marketing | L39: South | M39: 36687 | N39: 56505 | O39: 56505 | Q39: 46098 | R39: Rohit Gupta | S39: Marketing | T39: South | U39: 36687 | V39: 56505 | W39: 56505
A40: 46099 | B40: Simran Kaur | C40: Finance | D40: South | E40: 20000 | F40: 50614 | G40: 50614 | I40: 46099 | J40: Simran Kaur | K40: Finance | L40: South | M40: 20000 | N40: 50614 | O40: 50614 | Q40: 46099 | R40: Simran Kaur | S40: Finance | T40: South | U40: 20000 | V40: 50614 | W40: 50614
A41: 46100 | B41: Vikas Jain | C41: Finance | D41: North | E41: 89634 | F41: 79176 | G41: 79176 | I41: 46100 | J41: Vikas Jain | K41: Finance | L41: North | M41: 89634 | N41: 79176 | O41: 79176 | Q41: 46100 | R41: Vikas Jain | S41: Finance | T41: North | U41: 89634 | V41: 79176 | W41: 79176
A42: 46101 | B42: Priya Mehta | C42: Marketing | D42: South | E42: 62015 | F42: 69434 | G42: 69434 | I42: 46101 | J42: Priya Mehta | K42: Marketing | L42: South | M42: 62015 | N42: 69434 | O42: 69434 | Q42: 46101 | R42: Priya Mehta | S42: Marketing | T42: South | U42: 62015 | V42: 69434 | W42: 69434
A43: 46102 | B43: Karan Malhotra | C43: Marketing | D43: East | E43: 20000 | F43: 69434 | G43: 69434 | I43: 46102 | J43: Karan Malhotra | K43: Marketing | L43: East | M43: 20000 | N43: 69434 | O43: 69434 | Q43: 46102 | R43: Karan Malhotra | S43: Marketing | T43: East | U43: 20000 | V43: 69434 | W43: 69434
A44: 46103 | B44: Anjali Singh | C44: Finance | D44: West | E44: 20000 | F44: 60910 | G44: 60910 | I44: 46103 | J44: Anjali Singh | K44: Finance | L44: West | M44: 20000 | N44: 60910 | O44: 60910 | Q44: 46103 | R44: Anjali Singh | S44: Finance | T44: West | U44: 20000 | V44: 60910 | W44: 60910
A45: 46104 | B45: Rahul Kapoor | C45: Sales | D45: West | E45: 70837 | F45: 85222 | G45: 85222 | I45: 46104 | J45: Rahul Kapoor | K45: Sales | L45: West | M45: 70837 | N45: 85222 | O45: 85222 | Q45: 46104 | R45: Rahul Kapoor | S45: Sales | T45: West | U45: 70837 | V45: 85222 | W45: 85222
A46: 46111 | B46: Sneha Reddy | C46: Finance | D46: West | E46: 52700 | F46: 85222 | G46: 85222 | I46: 46111 | J46: Sneha Reddy | K46: Finance | L46: West | M46: 52700 | N46: 85222 | O46: 85222 | Q46: 46111 | R46: Sneha Reddy | S46: Finance | T46: West | U46: 52700 | V46: 85222 | W46: 85222
A47: 46112 | B47: Manish Yadav | C47: Sales | D47: North | E47: 44811 | F47: 65279 | G47: 65279 | I47: 46112 | J47: Manish Yadav | K47: Sales | L47: North | M47: 44811 | N47: 65279 | O47: 65279 | Q47: 46112 | R47: Manish Yadav | S47: Sales | T47: North | U47: 44811 | V47: 65279 | W47: 65279
A48: 46113 | B48: Pooja Bansal | C48: Marketing | D48: South | E48: 50833 | F48: 48220 | G48: 48220 | I48: 46113 | J48: Pooja Bansal | K48: Marketing | L48: South | M48: 50833 | N48: 48220 | O48: 48220 | Q48: 46113 | R48: Pooja Bansal | S48: Marketing | T48: South | U48: 50833 | V48: 48220 | W48: 48220
... A66: 46131 | B66: Payal Singh | C66: Sales | D66: East | E66: 84534 | F66: 74049 | G66: 74049 | I66: 46131 | J66: Payal Singh | K66: Sales | L66: East | M66: 84534 | N66: 74049 | O66: 74049 | Q66: 46131 | R66: Payal Singh | S66: Sales | T66: East | U66: 84534 | V66: 74049 | W66: 74049

Sheet filter
A1: Date | B1: Employee Name | C1: Department | D1: Region | E1: Sales (₹) | F1: Target (₹) | G1: Target (₹)
A2: 46096 | B2: Amit Sharma | C2: Finance | D2: East | E2: 78805 | F2: 47568 | G2: 47568
A3: 46097 | B3: Neha Verma | C3: Sales | D3: South | E3: 81218 | F3: 71354 | G3: 71354
A4: 46098 | B4: Rohit Gupta | C4: Marketing | D4: South | E4: 36687 | F4: 56505 | G4: 56505
A5: 46099 | B5: Simran Kaur | C5: Finance | D5: South | E5: 20000 | F5: 50614 | G5: 50614
A6: 46100 | B6: Vikas Jain | C6: Finance | D6: North | E6: 89634 | F6: 79176 | G6: 79176
A7: 46101 | B7: Priya Mehta | C7: Marketing | D7: South | E7: 62015 | F7: 69434 | G7: 69434
A8: 46102 | B8: Karan Malhotra | C8: Marketing | D8: East | E8: 20000 | F8: 69434 | G8: 69434
A9: 46103 | B9: Anjali Singh | C9: Finance | D9: West | E9: 20000 | F9: 60910 | G9: 60910
A10: 46104 | B10: Rahul Kapoor | C10: Sales | D10: West | E10: 70837 | F10: 85222 | G10: 85222
A11: 46111 | B11: Sneha Reddy | C11: Finance | D11: West | E11: 52700 | F11: 85222 | G11: 85222
A12: 46112 | B12: Manish Yadav | C12: Sales | D12: North | E12: 44811 | F12: 65279 | G12: 65279
A13: 46113 | B13: Pooja Bansal | C13: Marketing | D13: South | E13: 50833 | F13: 48220 | G13: 48220
... A31: 46131 | B31: Payal Singh | C31: Sales | D31: East | E31: 84534 | F31: 74049 | G31: 74049

Sheet Table
A1: Date | B1: Employee Name | C1: Department | D1: Region | E1: Sales (₹) | F1: Target (₹) | G1: Difference
A2: 46096 | B2: Amit Sharma | C2: Finance | D2: East | E2: 78805 | F2: 47568 | G2: =Table!$F2-Table!$E2 -> -31237
A3: 46097 | B3: Neha Verma | C3: Sales | D3: South | E3: 81218 | F3: 71354 | G3: =Table!$F3-Table!$E3 -> -9864
A4: 46098 | B4: Rohit Gupta | C4: Marketing | D4: South | E4: 36687 | F4: 56505 | G4: =Table!$F4-Table!$E4 -> 19818
A5: 46099 | B5: Simran Kaur | C5: Finance | D5: South | E5: 20000 | F5: 50614 | G5: =Table!$F5-Table!$E5 -> 30614
A6: 46100 | B6: Vikas Jain | C6: Finance | D6: North | E6: 89634 | F6: 79176 | G6: =Table!$F6-Table!$E6 -> -10458
A7: 46101 | B7: Priya Mehta | C7: Marketing | D7: South | E7: 62015 | F7: 69434 | G7: =Table!$F7-Table!$E7 -> 7419
A8: 46102 | B8: Karan Malhotra | C8: Marketing | D8: East | E8: 20000 | F8: 69434 | G8: =Table!$F8-Table!$E8 -> 49434
A9: 46103 | B9: Anjali Singh | C9: Finance | D9: West | E9: 20000 | F9: 60910 | G9: =Table!$F9-Table!$E9 -> 40910
A10: 46104 | B10: Rahul Kapoor | C10: Sales | D10: West | E10: 70837 | F10: 85222 | G10: =Table!$F10-Table!$E10 -> 14385
A11: 46111 | B11: Sneha Reddy | C11: Finance | D11: West | E11: 52700 | F11: 85222 | G11: =Table!$F11-Table!$E11 -> 32522
A12: 46112 | B12: Manish Yadav | C12: Sales | D12: North | E12: 44811 | F12: 65279 | G12: =Table!$F12-Table!$E12 -> 20468
A13: 46113 | B13: Pooja Bansal | C13: Marketing | D13: South | E13: 50833 | F13: 48220 | G13: =Table!$F13-Table!$E13 -> -2613
... A31: 46131 | B31: Payal Singh | C31: Sales | D31: East | E31: 84534 | F31: 74049 | G31: =Table!$F31-Table!$E31 -> -10485

Sheet Fill
A1: 1 | B1: 1 | C1: 1 | D1: 1 | E1: 1 | F1: 15 | G1: 2 | H1: 1000
A2: 2 | B2: 2 | C2: 2 | D2: 2 | E2: 3 | F2: 12 | G2: 4 | H2: 100
A3: 3 | B3: 3 | C3: 3 | D3: 3 | E3: 5 | F3: 9 | G3: 8 | H3: 10
A4: 4 | B4: 4 | C4: 4 | D4: 4 | E4: 7 | F4: 6 | G4: 16 | H4: 1
A5: 5 | B5: 5 | C5: 5 | D5: 5 | F5: 3 | G5: 32
A6: 6 | B6: 6 | C6: 6 | D6: 6
B8: {=_xlfn.SEQUENCE(5,5,1,1)} -> 1 | C8: 2 | D8: 3 | E8: 4 | F8: 5
B9: 6 | C9: 7 | D9: 8 | E9: 9 | F9: 10
B10: 11 | C10: 12 | D10: 13 | E10: 14 | F10: 15
B11: 16 | C11: 17 | D11: 18 | E11: 19 | F11: 20
B12: 21 | C12: 22 | D12: 23 | E12: 24 | F12: 25
B15: {=_xlfn.SEQUENCE(5,4,1,4)} -> 1 | C15: 5 | D15: 9 | E15: 13
B16: 17 | C16: 21 | D16: 25 | E16: 29
B17: 33 | C17: 37 | D17: 41 | E17: 45
B18: 49 | C18: 53 | D18: 57 | E18: 61
B19: 65 | C19: 69 | D19: 73 | E19: 77
B23: 46113 | D23: 46113 | F23: 46113 | H23: 46113 | J23: 46113 | K23: 46142 | L23: 46142 | M23: 46173 | O23: 46142
B24: 46114 | D24: 46114 | F24: 46115 | H24: 46114 | J24: 46143 | K24: 46172 | L24: 46172 | M24: 46203 | O24: 46507
B25: 46115 | D25: 46115 | F25: 46117 | H25: 46115 | J25: 46174 | K25: 46203 | L25: 46203 | M25: 46234 | O25: 46873
B26: 46116 | D26: 46116 | F26: 46119 | H26: 46118 | J26: 46204 | K26: 46233 | L26: 46233 | M26: 46265 | O26: 47238
B27: 46117 | D27: 46117 | F27: 46121 | H27: 46119 | J27: 46235 | K27: 46264 | L27: 46264 | M27: 46295 | O27: 47603
B28: 46118 | D28: 46118 | F28: 46123 | H28: 46120 | J28: 46266 | K28: 46295 | L28: 46295 | M28: 46326 | O28: 47968
B29: 46119 | D29: 46119 | F29: 46125 | H29: 46121 | J29: 46296 | K29: 46325 | L29: 46325 | M29: 46356 | O29: 48334
B30: 46120 | D30: 46120 | F30: 46127 | H30: 46122 | J30: 46327 | K30: 46356 | L30: 46356 | M30: 46387 | O30: 48699
B31: 46121 | D31: 46121 | F31: 46129 | H31: 46125 | J31: 46357 | K31: 46386 | L31: 46386 | M31: 46418 | O31: 49064
B32: 46122 | D32: 46122 | F32: 46131 | H32: 46126 | J32: 46388 | K32: 46417 | L32: 46417 | M32: 46446 | O32: 49429
B33: 46123 | D33: 46123 | F33: 46133 | H33: 46127 | J33: 46419 | K33: 46446 | L33: 46446 | M33: 46477 | O33: 49795
B34: 46124 | D34: 46124 | F34: 46135 | H34: 46128 | J34: 46447 | K34: 46476 | L34: 46476 | O34: 50160
B35: 46125 | D35: 46125 | F35: 46137 | H35: 46129 | O35: 50525
B36: 46126 | D36: 46126 | F36: 46139 | H36: 46132 | O36: 50890
B37: 46127 | D37: 46127 | F37: 46141 | H37: 46133 | O37: 51256
B38: 46128 | D38: 46128 | F38: 46143 | H38: 46134 | O38: 51621
B39: 46129 | D39: 46129 | F39: 46145 | H39: 46135 | O39: 51986
B40: 46130 | D40: 46130 | F40: 46147 | H40: 46136 | O40: 52351
B41: 46131 | D41: 46131 | F41: 46149 | H41: 46139 | O41: 52717
B42: 46132 | D42: 46132 | F42: 46151 | H42: 46140 | O42: 53082
B43: 46133 | D43: 46133 | F43: 46153 | H43: 46141 | O43: 53447
B44: 46134 | D44: 46134 | F44: 46155 | H44: 46142 | O44: 53812
B45: 46135 | D45: 46135 | F45: 46157 | H45: 46143 | O45: 54178
B46: 46136 | D46: 46136 | F46: 46159 | H46: 46146 | O46: 54543
...

Sheet Clipboard
A1: Date | B1: Employee Name | D1: Date | E1: Employee Name
A2: 46096 | B2: Amit Sharma | D2: 46096 | E2: Amit Sharma
A3: 46097 | B3: Neha Verma | D3: 46097 | E3: Neha Verma
A4: 46098 | B4: Rohit Gupta | D4: 46098 | E4: Rohit Gupta
A5: 46099 | B5: Simran Kaur | D5: 46099 | E5: Simran Kaur
C7: 46097
C8: Rohit Gupta
C9: 46097
C10: Rohit Gupta
C11: Neha Verma
C12: 46099
