Workbook

Sheet Cell Referencing (2)
A2: S no | B2: Names | C2: Hindi | D2: English | E2: Maths | F2: Science | G2: Total
A3: 1 | B3: Aarav Sharma | C3: 41 | D3: 39 | E3: 75 | F3: 34
A4: 2 | B4: Riya Verma | C4: 67 | D4: 57 | E4: 73 | F4: 47
A5: 3 | B5: Vivaan Mehta | C5: 22 | D5: 77 | E5: 29 | F5: 93
A6: 4 | B6: Ananya Iyer | C6: 58 | D6: 80 | E6: 28 | F6: 92
A7: 5 | B7: Karan Patel | C7: 89 | D7: 69 | E7: 92 | F7: 25
A8: 6 | B8: Sanya Malhotra | C8: 43 | D8: 20 | E8: 66 | F8: 50
A9: 7 | B9: Rahul Nair | C9: 21 | D9: 27 | E9: 70 | F9: 53
A10: 8 | B10: Pooja Deshmukh | C10: 21 | D10: 35 | E10: 36 | F10: 41
A11: 9 | B11: Aditya Reddy | C11: 61 | D11: 19 | E11: 25 | F11: 73
A12: 10 | B12: Meera Kapoor | C12: 69 | D12: 32 | E12: 59 | F12: 41
A13: 11 | B13: Rohan Bansal | C13: 27 | D13: 75 | E13: 68 | F13: 79
A14: 12 | B14: Ishita Choudhary | C14: 76 | D14: 54 | E14: 40 | F14: 30
... A17: 15 | B17: Kabir Saxena | C17: 15 | D17: 95 | E17: 29 | F17: 64
A30: Total Marks | F30: 400
A31: S no | B31: Names | C31: Hindi | D31: English | E31: Maths | F31: Science | G31: Total | H31: % | I31: %
A32: 1 | B32: Aarav Sharma | C32: 41 | D32: 39 | E32: 75 | F32: 34 | G32: =SUM(C32:F32) -> 189
A33: 2 | B33: Riya Verma | C33: 67 | D33: 57 | E33: 73 | F33: 47 | G33: =SUM(C33:F33) -> 244
A34: 3 | B34: Vivaan Mehta | C34: 22 | D34: 77 | E34: 29 | F34: 93 | G34: =SUM(C34:F34) -> 221
A35: 4 | B35: Ananya Iyer | C35: 58 | D35: 80 | E35: 28 | F35: 92 | G35: =SUM(C35:F35) -> 258
A36: 5 | B36: Karan Patel | C36: 89 | D36: 69 | E36: 92 | F36: 25 | G36: =SUM(C36:F36) -> 275
A37: 6 | B37: Sanya Malhotra | C37: 43 | D37: 20 | E37: 66 | F37: 50 | G37: =SUM(C37:F37) -> 179
A38: 7 | B38: Rahul Nair | C38: 21 | D38: 27 | E38: 70 | F38: 53 | G38: =SUM(C38:F38) -> 171
A39: 8 | B39: Pooja Deshmukh | C39: 21 | D39: 35 | E39: 36 | F39: 41 | G39: =SUM(C39:F39) -> 133
A40: 9 | B40: Aditya Reddy | C40: 61 | D40: 19 | E40: 25 | F40: 73 | G40: =SUM(C40:F40) -> 178
A41: 10 | B41: Meera Kapoor | C41: 69 | D41: 32 | E41: 59 | F41: 41 | G41: =SUM(C41:F41) -> 201
A42: 11 | B42: Rohan Bansal | C42: 27 | D42: 75 | E42: 68 | F42: 79 | G42: =SUM(C42:F42) -> 249
A43: 12 | B43: Ishita Choudhary | C43: 76 | D43: 54 | E43: 40 | F43: 30 | G43: =SUM(C43:F43) -> 200
... A46: 15 | B46: Kabir Saxena | C46: 15 | D46: 95 | E46: 29 | F46: 64 | G46: =SUM(C46:F46) -> 203
A61: Total Marks | F61: 400
A62: S no | B62: Names | C62: Hindi | D62: English | E62: Maths | F62: Science | G62: Total | H62: % | I62: Hindi % | J62: English % | K62: Maths % | L62: Science %
A63: 1 | B63: Aarav Sharma | C63: 41 | D63: 39 | E63: 75 | F63: 34 | G63: =SUM(C63:F63) -> 189 | H63: =G63/$F$61 -> 0.4725
A64: 2 | B64: Riya Verma | C64: 67 | D64: 57 | E64: 73 | F64: 47 | G64: =SUM(C64:F64) -> 244 | H64: =G64/$F$61 -> 0.61
A65: 3 | B65: Vivaan Mehta | C65: 22 | D65: 77 | E65: 29 | F65: 93 | G65: =SUM(C65:F65) -> 221 | H65: =G65/$F$61 -> 0.5525
A66: 4 | B66: Ananya Iyer | C66: 58 | D66: 80 | E66: 28 | F66: 92 | G66: =SUM(C66:F66) -> 258 | H66: =G66/$F$61 -> 0.645
A67: 5 | B67: Karan Patel | C67: 89 | D67: 69 | E67: 92 | F67: 25 | G67: =SUM(C67:F67) -> 275 | H67: =G67/$F$61 -> 0.6875
A68: 6 | B68: Sanya Malhotra | C68: 43 | D68: 20 | E68: 66 | F68: 50 | G68: =SUM(C68:F68) -> 179 | H68: =G68/$F$61 -> 0.4475
A69: 7 | B69: Rahul Nair | C69: 21 | D69: 27 | E69: 70 | F69: 53 | G69: =SUM(C69:F69) -> 171 | H69: =G69/$F$61 -> 0.4275
A70: 8 | B70: Pooja Deshmukh | C70: 21 | D70: 35 | E70: 36 | F70: 41 | G70: =SUM(C70:F70) -> 133 | H70: =G70/$F$61 -> 0.3325
A71: 9 | B71: Aditya Reddy | C71: 61 | D71: 19 | E71: 25 | F71: 73 | G71: =SUM(C71:F71) -> 178 | H71: =G71/$F$61 -> 0.445
...

Sheet Cell Referencing
A2: S no | B2: Names | C2: Hindi | D2: English | E2: Maths | F2: Science | G2: Total
A3: 1 | B3: Aarav Sharma | C3: 41 | D3: 39 | E3: 75 | F3: 34 | G3: =SUM(C3:F3) -> 189 | H3: =41+39+75+34 -> 189 | I3: =SUM(C3:F3) -> 189
A4: 2 | B4: Riya Verma | C4: 67 | D4: 57 | E4: 73 | F4: 47 | G4: =SUM(C4:F4) -> 244 | H4: =41+39+75+34 -> 189 | I4: =SUM(C4:F4) -> 244
A5: 3 | B5: Vivaan Mehta | C5: 22 | D5: 77 | E5: 29 | F5: 93 | G5: =SUM(C5:F5) -> 221 | H5: =41+39+75+34 -> 189 | I5: =SUM(C5:F5) -> 221
A6: 4 | B6: Ananya Iyer | C6: 58 | D6: 80 | E6: 28 | F6: 92 | G6: =SUM(C6:F6) -> 258 | H6: =41+39+75+34 -> 189 | I6: =SUM(C6:F6) -> 258
A7: 5 | B7: Karan Patel | C7: 89 | D7: 69 | E7: 92 | F7: 25 | G7: =SUM(C7:F7) -> 275 | H7: =41+39+75+34 -> 189 | I7: =SUM(C7:F7) -> 275
A8: 6 | B8: Sanya Malhotra | C8: 43 | D8: 20 | E8: 66 | F8: 50 | G8: =SUM(C8:F8) -> 179 | H8: =41+39+75+34 -> 189 | I8: =SUM(C8:F8) -> 179
A9: 7 | B9: Rahul Nair | C9: 21 | D9: 27 | E9: 70 | F9: 53 | G9: =SUM(C9:F9) -> 171 | H9: =41+39+75+34 -> 189 | I9: =SUM(C9:F9) -> 171
A10: 8 | B10: Pooja Deshmukh | C10: 21 | D10: 35 | E10: 36 | F10: 41 | G10: =SUM(C10:F10) -> 133 | H10: =41+39+75+34 -> 189 | I10: =SUM(C10:F10) -> 133
A11: 9 | B11: Aditya Reddy | C11: 61 | D11: 19 | E11: 25 | F11: 73 | G11: =SUM(C11:F11) -> 178 | H11: =41+39+75+34 -> 189 | I11: =SUM(C11:F11) -> 178
A12: 10 | B12: Meera Kapoor | C12: 69 | D12: 32 | E12: 59 | F12: 41 | G12: =SUM(C12:F12) -> 201 | H12: =41+39+75+34 -> 189 | I12: =SUM(C12:F12) -> 201
A13: 11 | B13: Rohan Bansal | C13: 27 | D13: 75 | E13: 68 | F13: 79 | G13: =SUM(C13:F13) -> 249 | H13: =41+39+75+34 -> 189 | I13: =SUM(C13:F13) -> 249
A14: 12 | B14: Ishita Choudhary | C14: 76 | D14: 54 | E14: 40 | F14: 30 | G14: =SUM(C14:F14) -> 200 | H14: =41+39+75+34 -> 189 | I14: =SUM(C14:F14) -> 200
... A17: 15 | B17: Kabir Saxena | C17: 15 | D17: 95 | E17: 29 | F17: 64 | G17: =SUM(C17:F17) -> 203 | H17: =41+39+75+34 -> 189 | I17: =SUM(C17:F17) -> 203
A30: Total Marks | F30: 400
A31: S no | B31: Names | C31: Hindi | D31: English | E31: Maths | F31: Science | G31: Total | H31: % | I31: %
A32: 1 | B32: Aarav Sharma | C32: 41 | D32: 39 | E32: 75 | F32: 34 | G32: =SUM(C32:F32) -> 189 | H32: =G32/400 -> 0.4725 | I32: =G32/$F$30 -> 0.4725
A33: 2 | B33: Riya Verma | C33: 67 | D33: 57 | E33: 73 | F33: 47 | G33: =SUM(C33:F33) -> 244 | H33: =G33/400 -> 0.61 | I33: =G33/$F$30 -> 0.61
A34: 3 | B34: Vivaan Mehta | C34: 22 | D34: 77 | E34: 29 | F34: 93 | G34: =SUM(C34:F34) -> 221 | H34: =G34/400 -> 0.5525 | I34: =G34/$F$30 -> 0.5525
A35: 4 | B35: Ananya Iyer | C35: 58 | D35: 80 | E35: 28 | F35: 92 | G35: =SUM(C35:F35) -> 258 | H35: =G35/400 -> 0.645 | I35: =G35/$F$30 -> 0.645
A36: 5 | B36: Karan Patel | C36: 89 | D36: 69 | E36: 92 | F36: 25 | G36: =SUM(C36:F36) -> 275 | H36: =G36/400 -> 0.6875 | I36: =G36/$F$30 -> 0.6875
A37: 6 | B37: Sanya Malhotra | C37: 43 | D37: 20 | E37: 66 | F37: 50 | G37: =SUM(C37:F37) -> 179 | H37: =G37/400 -> 0.4475 | I37: =G37/$F$30 -> 0.4475
A38: 7 | B38: Rahul Nair | C38: 21 | D38: 27 | E38: 70 | F38: 53 | G38: =SUM(C38:F38) -> 171 | H38: =G38/400 -> 0.4275 | I38: =G38/$F$30 -> 0.4275
A39: 8 | B39: Pooja Deshmukh | C39: 21 | D39: 35 | E39: 36 | F39: 41 | G39: =SUM(C39:F39) -> 133 | H39: =G39/400 -> 0.3325 | I39: =G39/$F$30 -> 0.3325
A40: 9 | B40: Aditya Reddy | C40: 61 | D40: 19 | E40: 25 | F40: 73 | G40: =SUM(C40:F40) -> 178 | H40: =G40/400 -> 0.445 | I40: =G40/$F$30 -> 0.445
A41: 10 | B41: Meera Kapoor | C41: 69 | D41: 32 | E41: 59 | F41: 41 | G41: =SUM(C41:F41) -> 201 | H41: =G41/400 -> 0.5025 | I41: =G41/$F$30 -> 0.5025
A42: 11 | B42: Rohan Bansal | C42: 27 | D42: 75 | E42: 68 | F42: 79 | G42: =SUM(C42:F42) -> 249 | H42: =G42/400 -> 0.6225 | I42: =G42/$F$30 -> 0.6225
A43: 12 | B43: Ishita Choudhary | C43: 76 | D43: 54 | E43: 40 | F43: 30 | G43: =SUM(C43:F43) -> 200 | H43: =G43/400 -> 0.5 | I43: =G43/$F$30 -> 0.5
... A46: 15 | B46: Kabir Saxena | C46: 15 | D46: 95 | E46: 29 | F46: 64 | G46: =SUM(C46:F46) -> 203 | H46: =G46/400 -> 0.5075 | I46: =G46/$F$30 -> 0.5075
A61: Total Marks | F61: 400
A62: S no | B62: Names | C62: Hindi | D62: English | E62: Maths | F62: Science | G62: Total | H62: % | I62: Hindi % | J62: English % | K62: Maths % | L62: Science %
A63: 1 | B63: Aarav Sharma | C63: 41 | D63: 39 | E63: 75 | F63: 34 | G63: =SUM(C63:F63) -> 189 | H63: =G63/$F$61 -> 0.4725 | I63: =C63/$G63 -> 0.21693122 | J63: =D63/$G63 -> 0.20634921 | K63: =E63/$G63 -> 0.3968254 | L63: =F63/$G63 -> 0.17989418
A64: 2 | B64: Riya Verma | C64: 67 | D64: 57 | E64: 73 | F64: 47 | G64: =SUM(C64:F64) -> 244 | H64: =G64/$F$61 -> 0.61 | I64: =C64/$G64 -> 0.27459016 | J64: =D64/$G64 -> 0.23360656 | K64: =E64/$G64 -> 0.29918033 | L64: =F64/$G64 -> 0.19262295
A65: 3 | B65: Vivaan Mehta | C65: 22 | D65: 77 | E65: 29 | F65: 93 | G65: =SUM(C65:F65) -> 221 | H65: =G65/$F$61 -> 0.5525 | I65: =C65/$G65 -> 0.099547511 | J65: =D65/$G65 -> 0.34841629 | K65: =E65/$G65 -> 0.13122172 | L65: =F65/$G65 -> 0.42081448
A66: 4 | B66: Ananya Iyer | C66: 58 | D66: 80 | E66: 28 | F66: 92 | G66: =SUM(C66:F66) -> 258 | H66: =G66/$F$61 -> 0.645 | I66: =C66/$G66 -> 0.2248062 | J66: =D66/$G66 -> 0.31007752 | K66: =E66/$G66 -> 0.10852713 | L66: =F66/$G66 -> 0.35658915
A67: 5 | B67: Karan Patel | C67: 89 | D67: 69 | E67: 92 | F67: 25 | G67: =SUM(C67:F67) -> 275 | H67: =G67/$F$61 -> 0.6875 | I67: =C67/$G67 -> 0.32363636 | J67: =D67/$G67 -> 0.25090909 | K67: =E67/$G67 -> 0.33454545 | L67: =F67/$G67 -> 0.090909091
A68: 6 | B68: Sanya Malhotra | C68: 43 | D68: 20 | E68: 66 | F68: 50 | G68: =SUM(C68:F68) -> 179 | H68: =G68/$F$61 -> 0.4475 | I68: =C68/$G68 -> 0.24022346 | J68: =D68/$G68 -> 0.11173184 | K68: =E68/$G68 -> 0.36871508 | L68: =F68/$G68 -> 0.27932961
A69: 7 | B69: Rahul Nair | C69: 21 | D69: 27 | E69: 70 | F69: 53 | G69: =SUM(C69:F69) -> 171 | H69: =G69/$F$61 -> 0.4275 | I69: =C69/$G69 -> 0.12280702 | J69: =D69/$G69 -> 0.15789474 | K69: =E69/$G69 -> 0.40935673 | L69: =F69/$G69 -> 0.30994152
A70: 8 | B70: Pooja Deshmukh | C70: 21 | D70: 35 | E70: 36 | F70: 41 | G70: =SUM(C70:F70) -> 133 | H70: =G70/$F$61 -> 0.3325 | I70: =C70/$G70 -> 0.15789474 | J70: =D70/$G70 -> 0.26315789 | K70: =E70/$G70 -> 0.27067669 | L70: =F70/$G70 -> 0.30827068
A71: 9 | B71: Aditya Reddy | C71: 61 | D71: 19 | E71: 25 | F71: 73 | G71: =SUM(C71:F71) -> 178 | H71: =G71/$F$61 -> 0.445 | I71: =C71/$G71 -> 0.34269663 | J71: =D71/$G71 -> 0.10674157 | K71: =E71/$G71 -> 0.14044944 | L71: =F71/$G71 -> 0.41011236
...

Sheet Text Formulas (2)
B1: Left | E1: Right | H1: Mid
B2: Names | C2: Prefix | E2: ID | F2: Suffix | H2: ID | I2: Suffix
B3: Mr. Aarav Sharma | E3: AXP-5678-MNO | H3: AXP-5678-MNO | I3: =MID(H3,5,4) -> 5678
B4: Mr. Rohan Iyer | E4: BTR-8492-KLM | H4: BTR-8492-KLM | I4: =MID(H4,5,4) -> 8492
B5: Mr. Aditya Mehta | E5: CQS-2345-XYZ | H5: CQS-2345-XYZ | I5: =MID(H5,5,4) -> 2345
B6: Mr. Vikram Malhotra | E6: DYN-6789-PQR | H6: DYN-6789-PQR | I6: =MID(H6,5,4) -> 6789
B7: Mr. Rajat Bansal | E7: EJM-4532-ABC | H7: EJM-4532-ABC | I7: =MID(H7,5,4) -> 4532
B8: Mr. Suresh Reddy | E8: FVK-9102-DEF | H8: FVK-9102-DEF | I8: =MID(H8,5,4) -> 9102
B9: Mr. Arjun Thakur | E9: GWL-3217-GHI | H9: GWL-3217-GHI | I9: =MID(H9,5,4) -> 3217
B10: Mr. Kunal Saxena | E10: HZS-7654-JKL | H10: HZS-7654-JKL | I10: =MID(H10,5,4) -> 7654
B11: Mr. Siddharth Rao | E11: JQP-1876-STU | H11: JQP-1876-STU | I11: =MID(H11,5,4) -> 1876
B12: Ms. Manisha Tripathi | E12: KRM-5923-VWX | H12: KRM-5923-VWX | I12: =MID(H12,5,4) -> 5923
B18: Length
B19: ID
B20: AXP-5678-MNO
B21: BTR-8492-KLM
B22: CQS-235-XYZ
B23: DYN-679- PQR
B24: EJM-4532-ABC
B25: FVK-9102-DEF
B26: GWL-3217-GHI
B27: HZS-7654-JKL
B28: JQP-1876-STU
B29: KRM-5923-VWX
... B60: Text
B61: Birth dates | C61: Days
B62: 14-06-1996
B63: 23-09-1998
B64: 37084
B65: 18-04-1995
B66: 30-07-2003
B67: 36841
B68: 25-05-1999
B69: 35491
B70: 19-08-2004
B71: 37478
B80: Lower | E80: Upper
B81: Names | C81: Small Letters | E81: Names | F81: Capital Letters | H81: Proper
B82: Mr. Aarav Sharma | E82: Mr. Aarav Sharma | H82: Names | I82: Sentence Case
B83: Mr. Rohan Iyer | E83: Mr. Rohan Iyer | H83: MR. AARAV SHARMA
...

Sheet Text Formulas
B1: Left | E1: Right | H1: Mid
B2: Names | C2: Prefix | E2: ID | F2: Suffix | H2: ID | I2: Suffix
B3: Mr. Aarav Sharma | C3: =LEFT(B3,3) -> Mr. | E3: AXP-5678-MNO | F3: =RIGHT(E3,3) -> MNO | H3: AXP-5678-MNO | I3: =MID(H3,5,4) -> 5678
B4: Mr. Rohan Iyer | C4: =LEFT(B4,3) -> Mr. | E4: BTR-8492-KLM | F4: =RIGHT(E4,3) -> KLM | H4: BTR-8492-KLM | I4: =MID(H4,5,4) -> 8492
B5: Mr. Aditya Mehta | C5: =LEFT(B5,3) -> Mr. | E5: CQS-2345-XYZ | F5: =RIGHT(E5,3) -> XYZ | H5: CQS-2345-XYZ | I5: =MID(H5,5,4) -> 2345
B6: Mr. Vikram Malhotra | C6: =LEFT(B6,3) -> Mr. | E6: DYN-6789-PQR | F6: =RIGHT(E6,3) -> PQR | H6: DYN-6789-PQR | I6: =MID(H6,5,4) -> 6789
B7: Mr. Rajat Bansal | C7: =LEFT(B7,3) -> Mr. | E7: EJM-4532-ABC | F7: =RIGHT(E7,3) -> ABC | H7: EJM-4532-ABC | I7: =MID(H7,5,4) -> 4532
B8: Mr. Suresh Reddy | C8: =LEFT(B8,3) -> Mr. | E8: FVK-9102-DEF | F8: =RIGHT(E8,3) -> DEF | H8: FVK-9102-DEF | I8: =MID(H8,5,4) -> 9102
B9: Mr. Arjun Thakur | C9: =LEFT(B9,3) -> Mr. | E9: GWL-3217-GHI | F9: =RIGHT(E9,3) -> GHI | H9: GWL-3217-GHI | I9: =MID(H9,5,4) -> 3217
B10: Mr. Kunal Saxena | C10: =LEFT(B10,3) -> Mr. | E10: HZS-7654-JKL | F10: =RIGHT(E10,3) -> JKL | H10: HZS-7654-JKL | I10: =MID(H10,5,4) -> 7654
B11: Mr. Siddharth Rao | C11: =LEFT(B11,3) -> Mr. | E11: JQP-1876-STU | F11: =RIGHT(E11,3) -> STU | H11: JQP-1876-STU | I11: =MID(H11,5,4) -> 1876
B12: Ms. Manisha Tripathi | C12: =LEFT(B12,3) -> Ms. | E12: KRM-5923-VWX | F12: =RIGHT(E12,3) -> VWX | H12: KRM-5923-VWX | I12: =MID(H12,5,4) -> 5923
B18: Len | D18: Length
B19: ID | D19: IDgth
B20: AXP-5678-MNO | C20: =LEN(B20) -> 12
B21: BTR-8492-KLM | C21: =LEN(B21) -> 12
B22: CQS-235-XYZ | C22: =LEN(B22) -> 11
B23: DYN-679- PQR | C23: =LEN(B23) -> 14
B24: EJM-4532-ABC | C24: =LEN(B24) -> 12
B25: FVK-9102-DEF | C25: =LEN(B25) -> 12
B26: GWL-3217-GHI | C26: =LEN(B26) -> 12
B27: HZS-7654-JKL | C27: =LEN(B27) -> 12
B28: JQP-1876-STU | C28: =LEN(B28) -> 12
B29: KRM-5923-VWX | C29: =LEN(B29) -> 12
B39: Trim | D39: unwanted spaces
B40: ID
B41: Mr. Aarav Sharma | C41: =TRIM(B41) -> Mr. Aarav Sharma
B42: Mr. Rohan Iyer | C42: =TRIM(B42) -> Mr. Rohan Iyer
B43: Mr. Aditya Mehta | C43: =TRIM(B43) -> Mr. Aditya Mehta
B44: Mr. Vikram Malhotra | C44: =TRIM(B44) -> Mr. Vikram Malhotra
B45: Mr. Rajat Bansal | C45: =TRIM(B45) -> Mr. Rajat Bansal
B46: Mr. Suresh Reddy | C46: =TRIM(B46) -> Mr. Suresh Reddy
B47: Mr. Arjun Thakur | C47: =TRIM(B47) -> Mr. Arjun Thakur
B48: Mr. Kunal Saxena | C48: =TRIM(B48) -> Mr. Kunal Saxena
B49: Mr. Siddharth Rao | C49: =TRIM(B49) -> Mr. Siddharth Rao
B50: Mr. Manish Tripathi | C50: =TRIM(B50) -> Mr. Manish Tripathi
B60: Text
B61: Birth dates | C61: Days
B62: 14-06-1996 | C62: =TEXT(B62,"dddd") -> Friday | D62: =TEXT(B62,"mmmm") -> June
B63: 23-09-1998 | C63: =TEXT(B63,"dddd") -> Wednesday | D63: =TEXT(B63,"mmmm") -> September
...

Sheet Notes
A1: Text Formulae (25) | H1: 25
A2: S No | B2: Formula | C2: Syntax | D2: Meaning (Hinglish) | E2: Usage | F2: Example | H2: 29
A3: 1 | B3: LEFT | C3: LEFT(TEXT, num_chars) | D3: Left side se characters nikaalta hai | E3: Starting letters extract karne ke liye | F3: =LEFT("Tannu",3) → Tan | H3: 28
A4: 2 | B4: RIGHT | C4: RIGHT(TEXT, num_chars) | D4: Right side se characters nikaalta hai | E4: Ending extract karne ke liye | F4: =RIGHT("Tannu",2) → nu | H4: 20
A5: 3 | B5: MID | C5: MID(TEXT, num_chars) | D5: Beech ka text nikaalta hai | E5: Specific position ka text | F5: =MID("Excel",2,3) → xce | H5: 20
A6: 4 | B6: LEN | C6: LEN(TEXT, num_chars) | D6: Total characters count karta hai | E6: Length check karne ke liye | F6: =LEN("Hello") → 5 | H6: 10
A7: 5 | B7: TRIM | C7: TRIM(TEXT, num_chars) | D7: Extra spaces hata deta hai | E7: Clean data ke liye | F7: =TRIM(" Hello ") → Hello | H7: 10
A8: 6 | B8: UPPER | C8: UPPER(TEXT, num_chars) | D8: Sabko capital bana deta hai | E8: Standard format | F8: =UPPER("excel") → EXCEL
A9: 7 | B9: LOWER | C9: LOWER(TEXT, num_chars) | D9: Sabko small letters me convert karta hai | E9: Email cleaning | F9: =LOWER("EXCEL") → excel
A10: 8 | B10: PROPER | C10: PROPER(TEXT, num_chars) | D10: Har word ka first letter capital | E10: Name formatting | F10: =PROPER("tannu singhal") → Tannu Singhal
A11: 9 | B11: CONCAT | C11: CONCAT(TEXT, num_chars) | D11: Multiple text join karta hai | E11: Data combine | F11: =CONCAT("A","B") → AB
A12: 10 | B12: CONCATENATE | C12: CONCATENATE(TEXT, num_chars) | D12: Same as CONCAT (old version) | E12: Combine text | F12: =CONCATENATE("Hi"," ","All") -> Hi All
A13: 11 | B13: TEXTJOIN | C13: TEXTJOIN(TEXT, num_chars) | D13: Join karta hai with separator | E13: Advanced joining | F13: =_xlfn.TEXTJOIN(",",TRUE,A2:A4) -> S No,1,2
A14: 12 | B14: FIND | C14: FIND(TEXT, num_chars) | D14: Case-sensitive search karta hai | E14: Position find karna | F14: =FIND("a","Tannu") → 2
A15: 13 | B15: SEARCH | C15: SEARCH(TEXT, num_chars) | D15: Case-insensitive search | E15: Flexible search | F15: =SEARCH("A","tannu") → 2
A16: 14 | B16: REPLACE | C16: REPLACE(TEXT, num_chars) | D16: Text replace karta hai position se | E16: Data correction | F16: =REPLACE("12345",2,2,"AA") -> 1AA45
A17: 15 | B17: SUBSTITUTE | C17: SUBSTITUTE(TEXT, num_chars) | D17: Specific text replace karta hai | E17: Word replace | F17: =SUBSTITUTE("Hi all","all","team") -> Hi team
A18: 16 | B18: VALUE | C18: VALUE(TEXT, num_chars) | D18: Text ko number me convert karta hai | E18: Numeric conversion | F18: =VALUE("123") → 123
A19: 17 | B19: TEXT | C19: TEXT(TEXT, num_chars) | D19: Number ko text format me convert | E19: Formatting | F19: =TEXT(100,"₹0") → ₹100
A20: 18 | B20: CLEAN | C20: CLEAN(TEXT, num_chars) | D20: Non-printable characters remove karta hai | E20: Imported data cleaning | F20: =CLEAN(A2) -> S No
A21: 19 | B21: CHAR | C21: CHAR(TEXT, num_chars) | D21: ASCII code se character return | E21: Special characters | F21: =CHAR(65) → A
A22: 20 | B22: REPT | C22: REPT(TEXT, num_chars) | D22: Text repeat karta hai | E22: Pattern banana | F22: =REPT("*",5) → *****
A23: Text Split , Ampersend , flashfill , Textbeforedelimeter , textafterdelimeter
A33: Statistical Formulae (30)
A34: S No | B34: Formula | C34: Syntax | D34: Meaning (Hinglish) | E34: Usage | F34: Example
A35: 1 | B35: AVERAGE | C35: AVERAGE(range) | D35: Average nikaalta hai | E35: Mean calculation | F35: =AVERAGE(10,20,30) → 20
A36: 2 | B36: MAX | C36: MAX(range) | D36: Sabse badi value | E36: Highest find | F36: =MAX(10,50,30) → 50
A37: 3 | B37: MIN | C37: MIN(range) | D37: Sabse chhoti value | E37: Lowest find | F37: =MIN(10,50,30) → 10
A38: 4 | B38: COUNT | C38: COUNT(range) | D38: Numbers count karta hai | E38: Numeric count | F38: =COUNT(1,2,"A") → 2
A39: 5 | B39: COUNTA | C39: COUNTA(range) | D39: Non-empty count | E39: Filled cells | F39: =COUNTA(1,"A") → 2
A40: 6 | B40: COUNTIF | C40: COUNTIF(range,criteria) | D40: Condition pe count | E40: Filtered count | F40: =COUNTIF(A2:A6,">10") -> 0
A41: 7 | B41: COUNTIFS | C41: COUNTIFS(range1,criteria1,...) | D41: Multi condition count | E41: Advanced filtering | F41: =COUNTIFS(A2:A6,">10",B2:B6,"A") -> 0
A42: 8 | B42: AVERAGEIF | C42: AVERAGEIF(range,criteria) | D42: Condition pe average | E42: Filtered avg | F42: =AVERAGEIF(A2:A6,">10") -> #DIV/0!
A43: 9 | B43: AVERAGEIFS | C43: AVERAGEIFS(avg_range,criteria_range1,criteria1,...) | D43: Multi condition avg | E43: Advanced avg | F43: =AVERAGEIFS(A2:A6,B2:B6,"A") -> #DIV/0!
A44: 10 | B44: SUM | C44: SUM(range) | D44: Total sum | E44: Total calc | F44: =SUM(10,20,30) → 60
A45: 11 | B45: SUMIF | C45: SUMIF(range,criteria,sum_range) | D45: Condition pe sum | E45: Filtered sum | F45: =SUMIF(A2:A6,">10",B2:B6) -> 0
A46: 12 | B46: SUMIFS | C46: SUMIFS(sum_range,criteria_range1,criteria1,...) | D46: Multi condition sum | E46: Complex analysis | F46: =SUMIFS(B2:B6,A2:A6,">10") -> 0
A47: 13 | B47: LARGE | C47: LARGE(range,k) | D47: kth largest | E47: Top values | F47: =LARGE(A2:A6,2) -> 3
A48: 14 | B48: SMALL | C48: SMALL(range,k) | D48: kth smallest | E48: Bottom values | F48: =SMALL(A2:A6,2) -> 2
A49: 15 | B49: RANK | C49: RANK(number,range) | D49: Rank deta hai | E49: Position | F49: =RANK(50,A2:A6) -> #N/A
...

Sheet Logical Formulas
A1: S no | B1: Students Name | C1: Hindi | D1: English | E1: Math | F1: Science | G1: Total | H1: % | I1: Status
A2: 1 | B2: Aarav Mehta | C2: 40 | D2: 38 | E2: 34 | F2: 77 | G2: =SUM(C2:F2) -> 189 | H2: =G2/400 -> 0.4725 | I2: =IF(H2>=50%,"Pass","Fail") -> Fail | J2: =IF(H2<50%,"Fail","Pass") -> Fail
A3: 2 | B3: Priya Sharma | C3: 35 | D3: 72 | E3: 76 | F3: 68 | G3: =SUM(C3:F3) -> 251 | H3: =G3/400 -> 0.6275 | I3: =IF(H3>=50%,"Pass","Fail") -> Pass | J3: =IF(H3<50%,"Fail","Pass") -> Pass
A4: 3 | B4: Ishaan Verma | C4: 85 | D4: 87 | E4: 58 | F4: 62 | G4: =SUM(C4:F4) -> 292 | H4: =G4/400 -> 0.73 | I4: =IF(H4>=50%,"Pass","Fail") -> Pass | J4: =IF(H4<50%,"Fail","Pass") -> Pass
A5: 4 | B5: Sneha Iyer | C5: 61 | D5: 52 | E5: 77 | F5: 67 | G5: =SUM(C5:F5) -> 257 | H5: =G5/400 -> 0.6425 | I5: =IF(H5>=50%,"Pass","Fail") -> Pass | J5: =IF(H5<50%,"Fail","Pass") -> Pass
A6: 5 | B6: Rohan Das | C6: 26 | D6: 91 | E6: 75 | F6: 38 | G6: =SUM(C6:F6) -> 230 | H6: =G6/400 -> 0.575 | I6: =IF(H6>=50%,"Pass","Fail") -> Pass | J6: =IF(H6<50%,"Fail","Pass") -> Pass
A7: 6 | B7: Kritika Nair | C7: 49 | D7: 55 | E7: 63 | F7: 73 | G7: =SUM(C7:F7) -> 240 | H7: =G7/400 -> 0.6 | I7: =IF(H7>=50%,"Pass","Fail") -> Pass | J7: =IF(H7<50%,"Fail","Pass") -> Pass
A8: 7 | B8: Yash Patel | C8: 44 | D8: 56 | E8: 92 | F8: 77 | G8: =SUM(C8:F8) -> 269 | H8: =G8/400 -> 0.6725 | I8: =IF(H8>=50%,"Pass","Fail") -> Pass | J8: =IF(H8<50%,"Fail","Pass") -> Pass
A9: 8 | B9: Ananya Reddy | C9: 95 | D9: 80 | E9: 62 | F9: 85 | G9: =SUM(C9:F9) -> 322 | H9: =G9/400 -> 0.805 | I9: =IF(H9>=50%,"Pass","Fail") -> Pass | J9: =IF(H9<50%,"Fail","Pass") -> Pass
A10: 9 | B10: Aditya Choudhary | C10: 64 | D10: 59 | E10: 85 | F10: 58 | G10: =SUM(C10:F10) -> 266 | H10: =G10/400 -> 0.665 | I10: =IF(H10>=50%,"Pass","Fail") -> Pass | J10: =IF(H10<50%,"Fail","Pass") -> Pass
A11: 10 | B11: Tanvi Joshi | C11: 32 | D11: 42 | E11: 30 | F11: 63 | G11: =SUM(C11:F11) -> 167 | H11: =G11/400 -> 0.4175 | I11: =IF(H11>=50%,"Pass","Fail") -> Fail | J11: =IF(H11<50%,"Fail","Pass") -> Fail
A12: 11 | B12: Nikhil Bansal | C12: 32 | D12: 68 | E12: 48 | F12: 95 | G12: =SUM(C12:F12) -> 243 | H12: =G12/400 -> 0.6075 | I12: =IF(H12>=50%,"Pass","Fail") -> Pass | J12: =IF(H12<50%,"Fail","Pass") -> Pass
A13: 12 | B13: Pooja Sinha | C13: 98 | D13: 53 | E13: 52 | F13: 57 | G13: =SUM(C13:F13) -> 260 | H13: =G13/400 -> 0.65 | I13: =IF(H13>=50%,"Pass","Fail") -> Pass | J13: =IF(H13<50%,"Fail","Pass") -> Pass
... A21: 20 | B21: Neha Jaiswal | C21: 26 | D21: 38 | E21: 33 | F21: 42 | G21: =SUM(C21:F21) -> 139 | H21: =G21/400 -> 0.3475 | I21: =IF(H21>=50%,"Pass","Fail") -> Fail | J21: =IF(H21<50%,"Fail","Pass") -> Fail
A31: S no | B31: Salesman | C31: Sales | D31: Rating | E31: IF And | F31: And | G31: Or | H31: IF or
A32: 1 | B32: Aarav Mehta | C32: 82269 | D32: 2 | E32: =IF(AND(C32>=50000,D32>=3),"Bonus Eligibile","No Bonus") -> No Bonus | F32: =AND(C32>=50000,D32>=3) -> FALSE | G32: =OR(C32>=50000,D32>=3) -> TRUE | H32: =IF(OR(C32>=50000,D32>=3),"Bonus Eligible", " No Bonus") -> Bonus Eligible
A33: 2 | B33: Priya Sharma | C33: 85056 | D33: 2 | E33: =IF(AND(C33>=50000,D33>=3),"Bonus Eligibile","No Bonus") -> No Bonus | F33: =AND(C33>=50000,D33>=3) -> FALSE | G33: =OR(C33>=50000,D33>=3) -> TRUE | H33: =IF(OR(C33>=50000,D33>=3),"Bonus Eligible", " No Bonus") -> Bonus Eligible
A34: 3 | B34: Ishaan Verma | C34: 65900 | D34: 3 | E34: =IF(AND(C34>=50000,D34>=3),"Bonus Eligibile","No Bonus") -> Bonus Eligibile | F34: =AND(C34>=50000,D34>=3) -> TRUE | G34: =OR(C34>=50000,D34>=3) -> TRUE | H34: =IF(OR(C34>=50000,D34>=3),"Bonus Eligible", " No Bonus") -> Bonus Eligible
A35: 4 | B35: Sneha Iyer | C35: 49825 | D35: 1 | E35: =IF(AND(C35>=50000,D35>=3),"Bonus Eligibile","No Bonus") -> No Bonus | F35: =AND(C35>=50000,D35>=3) -> FALSE | G35: =OR(C35>=50000,D35>=3) -> FALSE | H35: =IF(OR(C35>=50000,D35>=3),"Bonus Eligible", " No Bonus") -> No Bonus
A36: 5 | B36: Rohan Das | C36: 77583 | D36: 1 | E36: =IF(AND(C36>=50000,D36>=3),"Bonus Eligibile","No Bonus") -> No Bonus | F36: =AND(C36>=50000,D36>=3) -> FALSE | G36: =OR(C36>=50000,D36>=3) -> TRUE | H36: =IF(OR(C36>=50000,D36>=3),"Bonus Eligible", " No Bonus") -> Bonus Eligible
A37: 6 | B37: Kritika Nair | C37: 62039 | D37: 3 | E37: =IF(AND(C37>=50000,D37>=3),"Bonus Eligibile","No Bonus") -> Bonus Eligibile | F37: =AND(C37>=50000,D37>=3) -> TRUE | G37: =OR(C37>=50000,D37>=3) -> TRUE | H37: =IF(OR(C37>=50000,D37>=3),"Bonus Eligible", " No Bonus") -> Bonus Eligible
A38: 7 | B38: Yash Patel | C38: 49241 | D38: 4 | E38: =IF(AND(C38>=50000,D38>=3),"Bonus Eligibile","No Bonus") -> No Bonus | F38: =AND(C38>=50000,D38>=3) -> FALSE | G38: =OR(C38>=50000,D38>=3) -> TRUE | H38: =IF(OR(C38>=50000,D38>=3),"Bonus Eligible", " No Bonus") -> Bonus Eligible
A39: 8 | B39: Ananya Reddy | C39: 48046 | D39: 2 | E39: =IF(AND(C39>=50000,D39>=3),"Bonus Eligibile","No Bonus") -> No Bonus | F39: =AND(C39>=50000,D39>=3) -> FALSE | G39: =OR(C39>=50000,D39>=3) -> FALSE | H39: =IF(OR(C39>=50000,D39>=3),"Bonus Eligible", " No Bonus") -> No Bonus
A40: 9 | B40: Aditya Choudhary | C40: 13201 | D40: 4 | E40: =IF(AND(C40>=50000,D40>=3),"Bonus Eligibile","No Bonus") -> No Bonus | F40: =AND(C40>=50000,D40>=3) -> FALSE | G40: =OR(C40>=50000,D40>=3) -> TRUE | H40: =IF(OR(C40>=50000,D40>=3),"Bonus Eligible", " No Bonus") -> Bonus Eligible
A41: 10 | B41: Tanvi Joshi | C41: 63474 | D41: 5 | E41: =IF(AND(C41>=50000,D41>=3),"Bonus Eligibile","No Bonus") -> Bonus Eligibile | F41: =AND(C41>=50000,D41>=3) -> TRUE | G41: =OR(C41>=50000,D41>=3) -> TRUE | H41: =IF(OR(C41>=50000,D41>=3),"Bonus Eligible", " No Bonus") -> Bonus Eligible
A42: 11 | B42: Nikhil Bansal | C42: 67520 | D42: 1 | E42: =IF(AND(C42>=50000,D42>=3),"Bonus Eligibile","No Bonus") -> No Bonus | F42: =AND(C42>=50000,D42>=3) -> FALSE | G42: =OR(C42>=50000,D42>=3) -> TRUE | H42: =IF(OR(C42>=50000,D42>=3),"Bonus Eligible", " No Bonus") -> Bonus Eligible
A43: 12 | B43: Pooja Sinha | C43: 38646 | D43: 5 | E43: =IF(AND(C43>=50000,D43>=3),"Bonus Eligibile","No Bonus") -> No Bonus | F43: =AND(C43>=50000,D43>=3) -> FALSE | G43: =OR(C43>=50000,D43>=3) -> TRUE | H43: =IF(OR(C43>=50000,D43>=3),"Bonus Eligible", " No Bonus") -> Bonus Eligible
... A51: 20 | B51: Neha Jaiswal | C51: 81922 | D51: 5 | E51: =IF(AND(C51>=50000,D51>=3),"Bonus Eligibile","No Bonus") -> Bonus Eligibile | F51: =AND(C51>=50000,D51>=3) -> TRUE | G51: =OR(C51>=50000,D51>=3) -> TRUE | H51: =IF(OR(C51>=50000,D51>=3),"Bonus Eligible", " No Bonus") -> Bonus Eligible
A58: S no | B58: Students Name | C58: Hindi | D58: English | E58: Math | F58: Science | G58: Total | H58: % | I58: Grade | J58: Switch
A59: 1 | B59: Aarav Mehta | C59: 100 | D59: 100 | E59: 90 | F59: 90 | G59: =SUM(C59:F59) -> 380 | H59: =G59/400 -> 0.95 | I59: {=_xlfn.IFS(H59<30%,"D",H59<50%,"C",H59<75%,"B",H59<90%,"A",H59>90%,"A+")} -> A+ | J59: {=_xlfn.SWITCH(I59,"A+",10000,"A",5000,"B",2000,1000)} -> 10000 | L59: 0-30% | M59: D | N59: 1000
A60: 2 | B60: Priya Sharma | C60: 95 | D60: 85 | E60: 96 | F60: 95 | G60: =SUM(C60:F60) -> 371 | H60: =G60/400 -> 0.9275 | I60: {=_xlfn.IFS(H60<30%,"D",H60<50%,"C",H60<75%,"B",H60<90%,"A",H60>90%,"A+")} -> A+ | J60: {=_xlfn.SWITCH(I60,"A+",10000,"A",5000,"B",2000,1000)} -> 10000 | L60: 30%-50% | M60: C | N60: 1000
A61: 3 | B61: Ishaan Verma | C61: 85 | D61: 87 | E61: 58 | F61: 62 | G61: =SUM(C61:F61) -> 292 | H61: =G61/400 -> 0.73 | I61: {=_xlfn.IFS(H61<30%,"D",H61<50%,"C",H61<75%,"B",H61<90%,"A",H61>90%,"A+")} -> B | J61: {=_xlfn.SWITCH(I61,"A+",10000,"A",5000,"B",2000,1000)} -> 2000 | L61: 50%-75% | M61: B | N61: 2000
A62: 4 | B62: Sneha Iyer | C62: 61 | D62: 52 | E62: 77 | F62: 67 | G62: =SUM(C62:F62) -> 257 | H62: =G62/400 -> 0.6425 | I62: {=_xlfn.IFS(H62<30%,"D",H62<50%,"C",H62<75%,"B",H62<90%,"A",H62>90%,"A+")} -> B | J62: {=_xlfn.SWITCH(I62,"A+",10000,"A",5000,"B",2000,1000)} -> 2000 | L62: 75%-90% | M62: A | N62: 5000
A63: 5 | B63: Rohan Das | C63: 26 | D63: 91 | E63: 75 | F63: 38 | G63: =SUM(C63:F63) -> 230 | H63: =G63/400 -> 0.575 | I63: {=_xlfn.IFS(H63<30%,"D",H63<50%,"C",H63<75%,"B",H63<90%,"A",H63>90%,"A+")} -> B | J63: {=_xlfn.SWITCH(I63,"A+",10000,"A",5000,"B",2000,1000)} -> 2000 | L63: 90%-100% | M63: A+ | N63: 10000
A64: 6 | B64: Kritika Nair | C64: 49 | D64: 55 | E64: 63 | F64: 73 | G64: =SUM(C64:F64) -> 240 | H64: =G64/400 -> 0.6 | I64: {=_xlfn.IFS(H64<30%,"D",H64<50%,"C",H64<75%,"B",H64<90%,"A",H64>90%,"A+")} -> B | J64: {=_xlfn.SWITCH(I64,"A+",10000,"A",5000,"B",2000,1000)} -> 2000
A65: 7 | B65: Yash Patel | C65: 44 | D65: 56 | E65: 92 | F65: 77 | G65: =SUM(C65:F65) -> 269 | H65: =G65/400 -> 0.6725 | I65: {=_xlfn.IFS(H65<30%,"D",H65<50%,"C",H65<75%,"B",H65<90%,"A",H65>90%,"A+")} -> B | J65: {=_xlfn.SWITCH(I65,"A+",10000,"A",5000,"B",2000,1000)} -> 2000
A66: 8 | B66: Ananya Reddy | C66: 95 | D66: 80 | E66: 62 | F66: 85 | G66: =SUM(C66:F66) -> 322 | H66: =G66/400 -> 0.805 | I66: {=_xlfn.IFS(H66<30%,"D",H66<50%,"C",H66<75%,"B",H66<90%,"A",H66>90%,"A+")} -> A | J66: {=_xlfn.SWITCH(I66,"A+",10000,"A",5000,"B",2000,1000)} -> 5000
A67: 9 | B67: Aditya Choudhary | C67: 64 | D67: 59 | E67: 85 | F67: 58 | G67: =SUM(C67:F67) -> 266 | H67: =G67/400 -> 0.665 | I67: {=_xlfn.IFS(H67<30%,"D",H67<50%,"C",H67<75%,"B",H67<90%,"A",H67>90%,"A+")} -> B | J67: {=_xlfn.SWITCH(I67,"A+",10000,"A",5000,"B",2000,1000)} -> 2000
A68: 10 | B68: Tanvi Joshi | C68: 32 | D68: 42 | E68: 30 | F68: 63 | G68: =SUM(C68:F68) -> 167 | H68: =G68/400 -> 0.4175 | I68: {=_xlfn.IFS(H68<30%,"D",H68<50%,"C",H68<75%,"B",H68<90%,"A",H68>90%,"A+")} -> C | J68: {=_xlfn.SWITCH(I68,"A+",10000,"A",5000,"B",2000,1000)} -> 1000
A69: 11 | B69: Nikhil Bansal | C69: 32 | D69: 68 | E69: 48 | F69: 95 | G69: =SUM(C69:F69) -> 243 | H69: =G69/400 -> 0.6075 | I69: {=_xlfn.IFS(H69<30%,"D",H69<50%,"C",H69<75%,"B",H69<90%,"A",H69>90%,"A+")} -> B | J69: {=_xlfn.SWITCH(I69,"A+",10000,"A",5000,"B",2000,1000)} -> 2000
...

Sheet Date n Time Formulas (2)
B2: Current Date | F2: 45728 | G2: Current Time | K2: 0.49097222
B5: Date | C5: Text | D5: Day | E5: Month | F5: Year | G5: Date
B6: 41043
B7: 36126
B8: 45147
B9: 38383
B10: 42938
B11: 34247
B12: 40255
B13: 44536
B14: 36645
B15: 42258
A24: Holidays | B24: Start Date | C24: End Date | D24: Days | E24: Days360 | F24: Networkdays | G24: Networkdays (holidays) | H24: Networkdays.intl | I24: Networkdays.intl (HOLIDAY)
A25: 45385 | B25: 45604 | C25: 45646
A26: 45428 | B26: 45342 | C26: 45562
A27: 45509 | B27: 45680 | C27: 45723
A28: 45529 | B28: 45292 | C28: 45433
A29: 45535 | B29: 45441 | C29: 45595
A30: 45553 | B30: 45632 | C30: 45701
A31: 45590 | B31: 45526 | C31: 45724
A32: 45652 | B32: 45668 | C32: 45705
A33: 45693 | B33: 45509 | C33: 45763
A34: 45693 | B34: 45602 | C34: 45662
B45: Start Date | C45: Months | D45: Days | E45: Edate | F45: Eomonth
B46: 45604 | C46: 2 | D46: 60
B47: 45342 | C47: 3 | D47: 90
B48: 45680 | C48: 3 | D48: 65
B49: 45292 | C49: 4 | D49: 52
B50: 45441 | C50: 6 | D50: 62
B51: 45632 | C51: 5 | D51: 32
B52: 45526 | C52: 2 | D52: 60
B53: 45668 | C53: 3 | D53: 90
B54: 45509 | C54: 1 | D54: 30
B55: 45602 | C55: 2 | D55: 62
B63: Start Date | C63: Holidays | D63: Days | E63: Workday | F63: Workday (holiday) | G63: Workday.intl | H63: Workday.intl (holiday)
B64: 45604 | C64: 45385 | D64: 50
B65: 45342 | C65: 45428 | D65: 60
B66: 45680 | C66: 45509 | D66: 20
B67: 45292 | C67: 45529 | D67: 35
B68: 45441 | C68: 45535 | D68: 45
...

Sheet Date n Time Formulas
B2: Current Date | C2: =TODAY() -> 46130 | F2: 46122 | G2: Current Time | H2: =NOW() -> 46130.705 | K2: 0.61875
B5: Date | C5: Text | D5: Day | E5: Month | F5: Year | G5: Date
B6: 41043 | C6: =TEXT(B6,"ddd") -> Mon | D6: =DAY(B6) -> 14 | E6: =MONTH(B6) -> 5 | F6: =YEAR(B6) -> 2012 | G6: =DATE(F6,E6,D6) -> 41043
B7: 36126 | C7: =TEXT(B7,"ddd") -> Fri | D7: =DAY(B7) -> 27 | E7: =MONTH(B7) -> 11 | F7: =YEAR(B7) -> 1998 | G7: =DATE(F7,E7,D7) -> 36126
B8: 45147 | C8: =TEXT(B8,"ddd") -> Wed | D8: =DAY(B8) -> 9 | E8: =MONTH(B8) -> 8 | F8: =YEAR(B8) -> 2023 | G8: =DATE(F8,E8,D8) -> 45147
B9: 38383 | C9: =TEXT(B9,"ddd") -> Mon | D9: =DAY(B9) -> 31 | E9: =MONTH(B9) -> 1 | F9: =YEAR(B9) -> 2005 | G9: =DATE(F9,E9,D9) -> 38383
B10: 42938 | C10: =TEXT(B10,"ddd") -> Sat | D10: =DAY(B10) -> 22 | E10: =MONTH(B10) -> 7 | F10: =YEAR(B10) -> 2017 | G10: =DATE(F10,E10,D10) -> 42938
B11: 34247 | C11: =TEXT(B11,"ddd") -> Tue | D11: =DAY(B11) -> 5 | E11: =MONTH(B11) -> 10 | F11: =YEAR(B11) -> 1993 | G11: =DATE(F11,E11,D11) -> 34247
B12: 40255 | C12: =TEXT(B12,"ddd") -> Thu | D12: =DAY(B12) -> 18 | E12: =MONTH(B12) -> 3 | F12: =YEAR(B12) -> 2010 | G12: =DATE(F12,E12,D12) -> 40255
B13: 44536 | C13: =TEXT(B13,"ddd") -> Mon | D13: =DAY(B13) -> 6 | E13: =MONTH(B13) -> 12 | F13: =YEAR(B13) -> 2021 | G13: =DATE(F13,E13,D13) -> 44536
B14: 36645 | C14: =TEXT(B14,"ddd") -> Sat | D14: =DAY(B14) -> 29 | E14: =MONTH(B14) -> 4 | F14: =YEAR(B14) -> 2000 | G14: =DATE(F14,E14,D14) -> 36645
B15: 42258 | C15: =TEXT(B15,"ddd") -> Fri | D15: =DAY(B15) -> 11 | E15: =MONTH(B15) -> 9 | F15: =YEAR(B15) -> 2015 | G15: =DATE(F15,E15,D15) -> 42258
A24: Holidays | B24: Start Date | C24: End Date | D24: Days | E24: Days360 | F24: Networkdays | G24: Networkdays (holidays) | H24: Networkdays.intl | I24: Networkdays.intl (HOLIDAY)
A25: 46117 | B25: 46106 | C25: 46117 | D25: =_xlfn.DAYS(C25,B25) -> 11 | E25: =DAYS360(B25,C25) -> 10 | F25: =NETWORKDAYS(B25,C25) -> 8 | G25: =NETWORKDAYS(B25,C25,A25) -> 8 | H25: =NETWORKDAYS.INTL(B25,C25,11) -> 10 | I25: =NETWORKDAYS.INTL(B25,C25,11,A25) -> 10
A26: 46085 | B26: 46078 | C26: 46086 | D26: =_xlfn.DAYS(C26,B26) -> 8 | E26: =DAYS360(B26,C26) -> 10 | F26: =NETWORKDAYS(B26,C26) -> 7 | G26: =NETWORKDAYS(B26,C26,A26) -> 6 | H26: =NETWORKDAYS.INTL(B26,C26,11) -> 8 | I26: =NETWORKDAYS.INTL(B26,C26,11,A26) -> 7
A27: 45509 | B27: 45680 | C27: 45723 | D27: =_xlfn.DAYS(C27,B27) -> 43 | E27: =DAYS360(B27,C27) -> 44 | F27: =NETWORKDAYS(B27,C27) -> 32 | G27: =NETWORKDAYS(B27,C27,A27) -> 32 | H27: =NETWORKDAYS.INTL(B27,C27,11) -> 38 | I27: =NETWORKDAYS.INTL(B27,C27,11,A27) -> 38
A28: 45529 | B28: 45292 | C28: 45433 | D28: =_xlfn.DAYS(C28,B28) -> 141 | E28: =DAYS360(B28,C28) -> 140 | F28: =NETWORKDAYS(B28,C28) -> 102 | G28: =NETWORKDAYS(B28,C28,A28) -> 102 | H28: =NETWORKDAYS.INTL(B28,C28,11) -> 122 | I28: =NETWORKDAYS.INTL(B28,C28,11,A28) -> 122
A29: 45535 | B29: 45441 | C29: 45595 | D29: =_xlfn.DAYS(C29,B29) -> 154 | E29: =DAYS360(B29,C29) -> 151 | F29: =NETWORKDAYS(B29,C29) -> 111 | G29: =NETWORKDAYS(B29,C29,A29) -> 111 | H29: =NETWORKDAYS.INTL(B29,C29,11) -> 133 | I29: =NETWORKDAYS.INTL(B29,C29,11,A29) -> 132
A30: 45553 | B30: 45632 | C30: 45701 | D30: =_xlfn.DAYS(C30,B30) -> 69 | E30: =DAYS360(B30,C30) -> 67 | F30: =NETWORKDAYS(B30,C30) -> 50 | G30: =NETWORKDAYS(B30,C30,A30) -> 50 | H30: =NETWORKDAYS.INTL(B30,C30,11) -> 60 | I30: =NETWORKDAYS.INTL(B30,C30,11,A30) -> 60
A31: 45590 | B31: 45526 | C31: 45724 | D31: =_xlfn.DAYS(C31,B31) -> 198 | E31: =DAYS360(B31,C31) -> 196 | F31: =NETWORKDAYS(B31,C31) -> 142 | G31: =NETWORKDAYS(B31,C31,A31) -> 141 | H31: =NETWORKDAYS.INTL(B31,C31,11) -> 171 | I31: =NETWORKDAYS.INTL(B31,C31,11,A31) -> 170
A32: 45652 | B32: 45668 | C32: 45705 | D32: =_xlfn.DAYS(C32,B32) -> 37 | E32: =DAYS360(B32,C32) -> 36 | F32: =NETWORKDAYS(B32,C32) -> 26 | G32: =NETWORKDAYS(B32,C32,A32) -> 26 | H32: =NETWORKDAYS.INTL(B32,C32,11) -> 32 | I32: =NETWORKDAYS.INTL(B32,C32,11,A32) -> 32
A33: 45693 | B33: 45509 | C33: 45763 | D33: =_xlfn.DAYS(C33,B33) -> 254 | E33: =DAYS360(B33,C33) -> 251 | F33: =NETWORKDAYS(B33,C33) -> 183 | G33: =NETWORKDAYS(B33,C33,A33) -> 182 | H33: =NETWORKDAYS.INTL(B33,C33,11) -> 219 | I33: =NETWORKDAYS.INTL(B33,C33,11,A33) -> 218
A34: 45693 | B34: 45602 | C34: 45662 | D34: =_xlfn.DAYS(C34,B34) -> 60 | E34: =DAYS360(B34,C34) -> 59 | F34: =NETWORKDAYS(B34,C34) -> 43 | G34: =NETWORKDAYS(B34,C34,A34) -> 43 | H34: =NETWORKDAYS.INTL(B34,C34,11) -> 52 | I34: =NETWORKDAYS.INTL(B34,C34,11,A34) -> 52
B45: Start Date | C45: Months | D45: Days | E45: Edate | F45: Eomonth | H45: 46143 | I45: =EOMONTH(H45,0) -> 46173
B46: 45604 | C46: 2 | D46: 60 | E46: =EDATE(B46,C46) -> 45665 | F46: =EOMONTH(B46,C46) -> 45688
B47: 45342 | C47: 3 | D47: 90 | E47: =EDATE(B47,C47) -> 45432 | F47: =EOMONTH(B47,C47) -> 45443
B48: 45680 | C48: 3 | D48: 65 | E48: =EDATE(B48,C48) -> 45770 | F48: =EOMONTH(B48,C48) -> 45777
B49: 45292 | C49: 4 | D49: 52 | E49: =EDATE(B49,C49) -> 45413 | F49: =EOMONTH(B49,C49) -> 45443
B50: 45441 | C50: 6 | D50: 62 | E50: =EDATE(B50,C50) -> 45625 | F50: =EOMONTH(B50,C50) -> 45626
B51: 45632 | C51: 5 | D51: 32 | E51: =EDATE(B51,C51) -> 45783 | F51: =EOMONTH(B51,C51) -> 45808
B52: 45526 | C52: 2 | D52: 60 | E52: =EDATE(B52,C52) -> 45587 | F52: =EOMONTH(B52,C52) -> 45596
B53: 45668 | C53: 3 | D53: 90 | E53: =EDATE(B53,C53) -> 45758 | F53: =EOMONTH(B53,C53) -> 45777
B54: 45509 | C54: 1 | D54: 30 | E54: =EDATE(B54,C54) -> 45540 | F54: =EOMONTH(B54,C54) -> 45565
B55: 45602 | C55: 2 | D55: 62 | E55: =EDATE(B55,C55) -> 45663 | F55: =EOMONTH(B55,C55) -> 45688
B63: Start Date | C63: Holidays | D63: Days | E63: Workday | F63: Workday (holiday) | G63: Workday.intl | H63: Workday.intl (holiday)
B64: 46110 | C64: 46115 | D64: 10 | E64: =WORKDAY(B64,D64) -> 46122 | F64: =WORKDAY(B64,D64,C64) -> 46125 | G64: =WORKDAY.INTL(B64,D64,11) -> 46121 | H64: =WORKDAY.INTL(B64,D64,11,C64) -> 46122
B65: 45342 | C65: 45428 | D65: 60 | E65: =WORKDAY(B65,D65) -> 45426 | F65: =WORKDAY(B65,D65,C65) -> 45426 | G65: =WORKDAY.INTL(B65,D65,11) -> 45412 | H65: =WORKDAY.INTL(B65,D65,11,C65) -> 45412
B66: 45680 | C66: 45509 | D66: 20 | E66: =WORKDAY(B66,D66) -> 45708 | F66: =WORKDAY(B66,D66,C66) -> 45708 | G66: =WORKDAY.INTL(B66,D66,11) -> 45703 | H66: =WORKDAY.INTL(B66,D66,11,C66) -> 45703
B67: 45292 | C67: 45529 | D67: 35 | E67: =WORKDAY(B67,D67) -> 45341 | F67: =WORKDAY(B67,D67,C67) -> 45341 | G67: =WORKDAY.INTL(B67,D67,11) -> 45332 | H67: =WORKDAY.INTL(B67,D67,11,C67) -> 45332
B68: 45441 | C68: 45535 | D68: 45 | E68: =WORKDAY(B68,D68) -> 45504 | F68: =WORKDAY(B68,D68,C68) -> 45504 | G68: =WORKDAY.INTL(B68,D68,11) -> 45493 | H68: =WORKDAY.INTL(B68,D68,11,C68) -> 45493
...

Sheet Number Formulas
A1: Rand (0 to 1)
A2: =RAND() -> 0.0021902235 | B2: =RAND() -> 0.19636937 | C2: =RAND() -> 0.16405
A3: =RAND() -> 0.34639094 | B3: =RAND() -> 0.13355238 | C3: =RAND() -> 0.54592086
A4: =RAND() -> 0.099037107 | B4: =RAND() -> 0.82019816 | C4: =RAND() -> 0.52791368
A5: =RAND() -> 0.11721299 | B5: =RAND() -> 0.86531061 | C5: =RAND() -> 0.71289322
A6: =RAND() -> 0.59885354 | B6: =RAND() -> 0.29779912 | C6: =RAND() -> 0.13217502
A7: =RAND() -> 0.017868615 | B7: =RAND() -> 0.026714302 | C7: =RAND() -> 0.043508455
A10: Rand Between (Range)
A11: =RANDBETWEEN(0,100) -> 79 | B11: =RANDBETWEEN(0,100) -> 91 | C11: =RANDBETWEEN(0,100) -> 89
A12: =RANDBETWEEN(0,100) -> 10 | B12: =RANDBETWEEN(0,100) -> 70 | C12: =RANDBETWEEN(0,100) -> 65
A13: =RANDBETWEEN(0,100) -> 24 | B13: =RANDBETWEEN(0,100) -> 60 | C13: =RANDBETWEEN(0,100) -> 56
A14: =RANDBETWEEN(0,100) -> 94 | B14: =RANDBETWEEN(0,100) -> 83 | C14: =RANDBETWEEN(0,100) -> 100
A15: =RANDBETWEEN(0,100) -> 59 | B15: =RANDBETWEEN(0,100) -> 52 | C15: =RANDBETWEEN(0,100) -> 31
A16: =RANDBETWEEN(0,100) -> 82 | B16: =RANDBETWEEN(0,100) -> 95 | C16: =RANDBETWEEN(0,100) -> 43
A17: =RANDBETWEEN(0,100) -> 15 | B17: =RANDBETWEEN(0,100) -> 55 | C17: =RANDBETWEEN(0,100) -> 40
A18: =RANDBETWEEN(0,100) -> 60 | B18: =RANDBETWEEN(0,100) -> 24 | C18: =RANDBETWEEN(0,100) -> 42
A22: Rand Array
A23: {=_xlfn.RANDARRAY(5,4,0,100,TRUE)} -> 84 | B23: 45 | C23: 36 | D23: 22
A24: 56 | B24: 65 | C24: 77 | D24: 72
A25: 60 | B25: 35 | C25: 49 | D25: 69
A26: 14 | B26: 96 | C26: 20 | D26: 10
A27: 38 | B27: 64 | C27: 12 | D27: 30
A31: Rand Array
A32: 41 | B32: 49 | C32: 92 | D32: 33
A33: 23 | B33: 12 | C33: 43 | D33: 29
A34: 77 | B34: 32 | C34: 5 | D34: 97
A35: 56 | B35: 66 | C35: 91 | D35: 21
A36: 89 | B36: 19 | C36: 10 | D36: 57
A43: 30707 | C43: 1 | D43: =LARGE(A43:A50,C43) -> 94832 | E43: =SMALL(A43:A50,C43) -> 11148 | F43: =SMALL($A$43:$A$50,C43) -> 11148
A44: 29747 | C44: 2 | D44: =LARGE(A44:A51,C44) -> 88535 | E44: =SMALL(A44:A51,C44) -> 29747 | F44: =SMALL($A$43:$A$50,C44) -> 29747
A45: 45679 | C45: 3 | D45: =LARGE(A45:A52,C45) -> 64561 | E45: =SMALL(A45:A52,C45) -> 45679 | F45: =SMALL($A$43:$A$50,C45) -> 30707
A46: 94832
A47: 64561
A48: 88535
A49: 37974
A50: 11148
A55: Round | D55: Round up | G55: Round Down | I55: Integer | J55: Trunc
A56: 1318.0083 | B56: =ROUND(A56,2) -> 1318.01 | D56: 1318.0083 | E56: =ROUNDUP(D56,2) -> 1318.01 | G56: 1318.0083 | H56: =ROUNDDOWN(G56,2) -> 1318 | I56: =INT(G56) -> 1318 | J56: =TRUNC(G56,1) -> 1318
A57: 4504.4012 | B57: =ROUND(A57,2) -> 4504.4 | D57: 4504.4012 | E57: =ROUNDUP(D57,2) -> 4504.41 | G57: 4504.4012 | H57: =ROUNDDOWN(G57,2) -> 4504.4 | I57: =INT(G57) -> 4504 | J57: =TRUNC(G57,1) -> 4504.4
A58: 1469.1423 | B58: =ROUND(A58,2) -> 1469.14 | D58: 1469.1423 | E58: =ROUNDUP(D58,2) -> 1469.15 | G58: 1469.1423 | H58: =ROUNDDOWN(G58,2) -> 1469.14 | I58: =INT(G58) -> 1469 | J58: =TRUNC(G58,1) -> 1469.1
...

Sheet Sumif etc (2)
A3: Party Names | B3: Sales | D3: Party Names | E3: Total Sales | F3: Average Sale | G3: Count Of Sale
A4: SwiftNova Enterprises | B4: 24750 | D4: SwiftNova Enterprises
A5: BluePeak Solutions | B5: 43891 | D5: BluePeak Solutions
A6: EliteCrest Innovations | B6: 36623 | D6: EliteCrest Innovations
A7: QuantumByte Technologies | B7: 33686 | D7: QuantumByte Technologies
A8: GoldenLeaf Ventures | B8: 37488 | D8: GoldenLeaf Ventures
A9: UrbanNest Interiors | B9: 21012 | D9: UrbanNest Interiors
A10: Vertex Synergy | B10: 34133 | D10: Vertex Synergy
A11: EverGlow Essentials | B11: 25015 | D11: EverGlow Essentials
A12: TruHarvest Organics | B12: 24185 | D12: TruHarvest Organics
A13: StellarEdge Consulting | B13: 27419 | D13: StellarEdge Consulting
A14: SwiftNova Enterprises | B14: 20989 | D14: Total Sale
A15: BluePeak Solutions | B15: 37327
A16: EliteCrest Innovations | B16: 14753
A17: QuantumByte Technologies | B17: 16689
A18: GoldenLeaf Ventures | B18: 38507
A19: EliteCrest Innovations | B19: 14720
A20: QuantumByte Technologies | B20: 38768
A21: GoldenLeaf Ventures | B21: 45280
A22: UrbanNest Interiors | B22: 49176
A23: Vertex Synergy | B23: 39695
A24: EverGlow Essentials | B24: 19380
A25: TruHarvest Organics | B25: 32705
A26: StellarEdge Consulting | B26: 37700
... A341: EverGlow Essentials | B341: 17811
B342: =SUM(B4:B341) -> 10175331

Sheet Sumif etc
A1: Party Names | B1: Sales | D1: Party Names | E1: Total Sales | F1: Average Sale | G1: Count Of Sale
A2: SwiftNova Enterprises | B2: 24750 | D2: SwiftNova Enterprises | E2: =SUMIF($A$2:$A$339,$D2,$B$2:$B$339) -> 805869 | F2: =AVERAGEIF($A$2:$A$339,D2,$B$2:$B$339) -> 28781.036 | G2: =COUNTIF($A$2:$A$339,D2) -> 28 | K2: Attendance Tracker 365
A3: BluePeak Solutions | B3: 43891 | D3: BluePeak Solutions | E3: =SUMIF($A$2:$A$339,$D3,$B$2:$B$339) -> 847774 | F3: =AVERAGEIF($A$2:$A$339,D3,$B$2:$B$339) -> 30277.643 | G3: =COUNTIF($A$2:$A$339,D3) -> 28 | K3: S no | L3: Students Name | M3: Mon | N3: Tue | O3: Wed | P3: Thu | Q3: Fri | R3: Present | S3: Absent
A4: EliteCrest Innovations | B4: 36623 | D4: EliteCrest Innovations | E4: =SUMIF($A$2:$A$339,$D4,$B$2:$B$339) -> 896206 | F4: =AVERAGEIF($A$2:$A$339,D4,$B$2:$B$339) -> 27157.758 | G4: =COUNTIF($A$2:$A$339,D4) -> 33 | K4: 1 | L4: Aarav Sharma | M4: TRUE | N4: FALSE | O4: FALSE | P4: FALSE | Q4: FALSE | R4: =COUNTIF(M4:Q4,"True") -> 1 | S4: =COUNTIF(M4:Q4,"False") -> 4
A5: QuantumByte Technologies | B5: 33686 | D5: QuantumByte Technologies | E5: =SUMIF($A$2:$A$339,$D5,$B$2:$B$339) -> 913593 | F5: =AVERAGEIF($A$2:$A$339,D5,$B$2:$B$339) -> 27684.636 | G5: =COUNTIF($A$2:$A$339,D5) -> 33 | K5: 2 | L5: Kavya Iyer | M5: FALSE | N5: TRUE | O5: TRUE | P5: TRUE | Q5: TRUE | R5: =COUNTIF(M5:Q5,"True") -> 4 | S5: =COUNTIF(M5:Q5,"False") -> 1
A6: GoldenLeaf Ventures | B6: 37488 | D6: GoldenLeaf Ventures | E6: =SUMIF($A$2:$A$339,$D6,$B$2:$B$339) -> 1361323 | F6: =AVERAGEIF($A$2:$A$339,D6,$B$2:$B$339) -> 32412.452 | G6: =COUNTIF($A$2:$A$339,D6) -> 42 | K6: 3 | L6: Rohan Mehta | M6: FALSE | N6: TRUE | O6: TRUE | P6: TRUE | Q6: TRUE | R6: =COUNTIF(M6:Q6,"True") -> 4 | S6: =COUNTIF(M6:Q6,"False") -> 1
A7: UrbanNest Interiors | B7: 21012 | D7: UrbanNest Interiors | E7: =SUMIF($A$2:$A$339,$D7,$B$2:$B$339) -> 590284 | F7: =AVERAGEIF($A$2:$A$339,D7,$B$2:$B$339) -> 31067.579 | G7: =COUNTIF($A$2:$A$339,D7) -> 19 | K7: 4 | L7: Sneha Reddy | M7: TRUE | N7: TRUE | O7: TRUE | P7: TRUE | Q7: TRUE | R7: =COUNTIF(M7:Q7,"True") -> 5 | S7: =COUNTIF(M7:Q7,"False") -> 0
A8: Vertex Synergy | B8: 34133 | D8: Vertex Synergy | E8: =SUMIF($A$2:$A$339,$D8,$B$2:$B$339) -> 1012579 | F8: =AVERAGEIF($A$2:$A$339,D8,$B$2:$B$339) -> 29781.735 | G8: =COUNTIF($A$2:$A$339,D8) -> 34 | K8: 5 | L8: Aditya Verma | M8: TRUE | N8: TRUE | O8: TRUE | P8: TRUE | Q8: TRUE | R8: =COUNTIF(M8:Q8,"True") -> 5 | S8: =COUNTIF(M8:Q8,"False") -> 0
A9: EverGlow Essentials | B9: 25015 | D9: EverGlow Essentials | E9: =SUMIF($A$2:$A$339,$D9,$B$2:$B$339) -> 1176087 | F9: =AVERAGEIF($A$2:$A$339,D9,$B$2:$B$339) -> 29402.175 | G9: =COUNTIF($A$2:$A$339,D9) -> 40 | K9: 6 | L9: Priya Nair | M9: FALSE | N9: TRUE | O9: TRUE | P9: TRUE | Q9: TRUE | R9: =COUNTIF(M9:Q9,"True") -> 4 | S9: =COUNTIF(M9:Q9,"False") -> 1
A10: TruHarvest Organics | B10: 24185 | D10: TruHarvest Organics | E10: =SUMIF($A$2:$A$339,$D10,$B$2:$B$339) -> 1408626 | F10: =AVERAGEIF($A$2:$A$339,D10,$B$2:$B$339) -> 30622.304 | G10: =COUNTIF($A$2:$A$339,D10) -> 46 | K10: 7 | L10: Arjun Singh | M10: TRUE | N10: TRUE | O10: TRUE | P10: TRUE | Q10: TRUE | R10: =COUNTIF(M10:Q10,"True") -> 5 | S10: =COUNTIF(M10:Q10,"False") -> 0
A11: StellarEdge Consulting | B11: 27419 | D11: StellarEdge Consulting | E11: =SUMIF($A$2:$A$339,$D11,$B$2:$B$339) -> 1162990 | F11: =AVERAGEIF($A$2:$A$339,D11,$B$2:$B$339) -> 33228.286 | G11: =COUNTIF($A$2:$A$339,D11) -> 35
A12: SwiftNova Enterprises | B12: 20989 | D12: Total Sale | E12: =SUM(E2:E11) -> 10175331
A13: BluePeak Solutions | B13: 37327
A14: EliteCrest Innovations | B14: 14753 | K14: Attendance Tracker Normal
A15: QuantumByte Technologies | B15: 16689 | K15: S no | L15: Students Name | M15: Mon | N15: Tue | O15: Wed | P15: Thu | Q15: Fri | R15: Present | S15: Absent
A16: GoldenLeaf Ventures | B16: 38507 | K16: 1 | L16: Aarav Sharma | M16: P | N16: P | O16: P | P16: P | Q16: O | R16: =COUNTIF(M16:Q16,"P") -> 4 | S16: =COUNTIF(M16:Q16,"O") -> 1
A17: EliteCrest Innovations | B17: 14720 | K17: 2 | L17: Kavya Iyer | M17: O | N17: P | O17: O | P17: O | Q17: P | R17: =COUNTIF(M17:Q17,"P") -> 2 | S17: =COUNTIF(M17:Q17,"O") -> 3
A18: QuantumByte Technologies | B18: 38768 | K18: 3 | L18: Rohan Mehta | M18: P | N18: P | O18: O | P18: P | Q18: O | R18: =COUNTIF(M18:Q18,"P") -> 3 | S18: =COUNTIF(M18:Q18,"O") -> 2
A19: GoldenLeaf Ventures | B19: 45280 | K19: 4 | L19: Sneha Reddy | M19: O | N19: O | O19: P | P19: O | Q19: P | R19: =COUNTIF(M19:Q19,"P") -> 2 | S19: =COUNTIF(M19:Q19,"O") -> 3
A20: UrbanNest Interiors | B20: 49176 | K20: 5 | L20: Aditya Verma | M20: P | N20: O | O20: P | P20: O | Q20: P | R20: =COUNTIF(M20:Q20,"P") -> 3 | S20: =COUNTIF(M20:Q20,"O") -> 2
A21: Vertex Synergy | B21: 39695 | K21: 6 | L21: Priya Nair | M21: O | N21: P | O21: P | P21: O | Q21: P | R21: =COUNTIF(M21:Q21,"P") -> 3 | S21: =COUNTIF(M21:Q21,"O") -> 2
A22: EverGlow Essentials | B22: 19380 | K22: 7 | L22: Arjun Singh | M22: P | N22: O | O22: P | P22: P | Q22: O | R22: =COUNTIF(M22:Q22,"P") -> 3 | S22: =COUNTIF(M22:Q22,"O") -> 2
A23: TruHarvest Organics | B23: 32705
A24: StellarEdge Consulting | B24: 37700
A25: Vertex Synergy | B25: 25793
A26: EverGlow Essentials | B26: 10459
A27: TruHarvest Organics | B27: 31197
A28: StellarEdge Consulting | B28: 28369
A29: SwiftNova Enterprises | B29: 25100
A30: BluePeak Solutions | B30: 10238
A31: EliteCrest Innovations | B31: 33922
A32: QuantumByte Technologies | B32: 22743
A33: GoldenLeaf Ventures | B33: 36685
A34: TruHarvest Organics | B34: 37198
... A339: EverGlow Essentials | B339: 17811
B340: =SUBTOTAL(9,B2:B339) -> 10175331

Sheet Master data
A1: S no | B1: Date | C1: Month | D1: Name | E1: Product Name | F1: Category | G1: Region | H1: City | I1: State | J1: Gender | K1: Quantity | L1: Rate | M1: Amount
A2: 1 | B2: 46061 | C2: =TEXT(B2,"mmm") -> Feb | D2: Bharat Innovations | E2: Speaker | F2: Electronic | G2: North | H2: Delhi | I2: Delhi | J2: Male | K2: 4292 | L2: 783 | M2: 3360636
A3: 2 | B3: 45800 | C3: =TEXT(B3,"mmm") -> May | D3: Green Leaf Enterprises | E3: Earbuds | F3: Electronic | G3: West | H3: Mumbai | I3: Maharashtra | J3: Male | K3: 8037 | L3: 578 | M3: 4645386
A4: =A3 -> 2 | B4: =B3 -> 45800 | C4: =TEXT(B4,"mmm") -> May | D4: =D3 -> Green Leaf Enterprises | E4: =E3 -> Earbuds | F4: =F3 -> Electronic | G4: =G3 -> West | H4: =H3 -> Mumbai | I4: =I3 -> Maharashtra | J4: =J3 -> Male | K4: =K3 -> 8037 | ... M4: =M3 -> 4645386
A5: 4 | B5: 46051 | C5: =TEXT(B5,"mmm") -> Jan | D5: Mystic India Exports | E5: Earbuds | F5: Electronic | G5: South | H5: Chennai | I5: Tamil Nadu | J5: Male | K5: 3941 | L5: 905 | M5: 3566605
A6: =A5 -> 4 | B6: =B5 -> 46051 | C6: =TEXT(B6,"mmm") -> Jan | D6: Green Leaf Enterprises | E6: =E5 -> Earbuds | F6: =F5 -> Electronic | G6: =G5 -> South | H6: =H5 -> Chennai | I6: =I5 -> Tamil Nadu | J6: =J5 -> Male | K6: =K5 -> 3941 | L6: =L5 -> 905 | M6: =M5 -> 3566605
A7: 6 | B7: 45802 | C7: =TEXT(B7,"mmm") -> May | D7: Green Leaf Enterprises | E7: Women dress | F7: Fashion | G7: South | H7: Hyderabad | I7: Telangana | J7: Male | K7: 4261 | L7: 954 | M7: 4064994
A8: =A7 -> 6 | B8: =B7 -> 45802 | C8: =TEXT(B8,"mmm") -> May | D8: Green Leaf Enterprises | E8: =E7 -> Women dress | F8: =F7 -> Fashion | G8: =G7 -> South | H8: =H7 -> Hyderabad | I8: =I7 -> Telangana | J8: =J7 -> Male | K8: =K7 -> 4261 | L8: =L7 -> 954 | M8: =M7 -> 4064994
A9: 8 | B9: 45907 | C9: =TEXT(B9,"mmm") -> Sep | D9: Zenith Construction Co. | E9: Speaker | F9: Electronic | G9: West | H9: Surat | I9: Gujarat | J9: Female | K9: 1631 | L9: 508 | M9: 828548
A10: =A9 -> 8 | B10: =B9 -> 45907 | C10: =TEXT(B10,"mmm") -> Sep | D10: =D9 -> Zenith Construction Co. | E10: =E9 -> Speaker | F10: =F9 -> Electronic | G10: =G9 -> West | H10: =H9 -> Surat | I10: =I9 -> Gujarat | J10: =J9 -> Female | K10: =K9 -> 1631 | ... M10: =M9 -> 828548
A11: 10 | B11: 46060 | C11: =TEXT(B11,"mmm") -> Feb | D11: Divine Creations | E11: Speaker | F11: Electronic | G11: North | H11: Kanpur | I11: Uttar Pradesh | J11: Female | K11: 4283 | L11: 804 | M11: 3443532
A12: 11 | B12: 45831 | C12: =TEXT(B12,"mmm") -> Jun | D12: Metro Tech Solutions | E12: Speaker | F12: Electronic | G12: West | H12: Nagpur | I12: Maharashtra | J12: Female | K12: 4249 | L12: 842 | M12: 3577658
A13: 12 | B13: 45941 | C13: =TEXT(B13,"mmm") -> Oct | D13: True Path Logistics | E13: Speaker | F13: Electronic | G13: Central | H13: Indore | I13: Madhya Pradesh | J13: Female | K13: 1902 | L13: 671 | M13: 1276242
A14: 13 | B14: 45976 | C14: =TEXT(B14,"mmm") -> Nov | D14: Green Leaf Enterprises | E14: Male dress | F14: Fashion | G14: West | H14: Thane | I14: Maharashtra | J14: Female | K14: 6166 | L14: 894 | M14: 5512404
A15: 14 | B15: 46049 | C15: =TEXT(B15,"mmm") -> Jan | D15: Green Leaf Enterprises | E15: Male dress | F15: Fashion | G15: North (Union Territory) | H15: Chandigarh | I15: Chandigarh | J15: Female | K15: 3669 | L15: 541 | M15: 1984929
A16: 15 | B16: 46078 | C16: =TEXT(B16,"mmm") -> Feb | D16: Green Leaf Enterprises | E16: Male dress | F16: Fashion | G16: Central | H16: Bhopal | I16: Madhya Pradesh | J16: Female | K16: 4667 | L16: 646 | M16: 3014882
A17: 16 | B17: 46033 | C17: =TEXT(B17,"mmm") -> Jan | D17: Visionary Holdings | E17: Male dress | F17: Fashion | G17: South | H17: Visakhapatnam | I17: Andhra Pradesh | J17: Female | K17: 6722 | L17: 671 | M17: 4510462
A18: 17 | B18: 45865 | C18: =TEXT(B18,"mmm") -> Jul | D18: Stellar Design Studio | E18: Male dress | F18: Fashion | G18: East | H18: Patna | I18: Bihar | J18: Female | K18: 8821 | L18: 611 | M18: 5389631
A19: =A18 -> 17 | B19: =B18 -> 45865 | C19: =TEXT(B19,"mmm") -> Jul | D19: =D18 -> Stellar Design Studio | E19: =E18 -> Male dress | F19: =F18 -> Fashion | G19: =G18 -> East | H19: =H18 -> Patna | I19: =I18 -> Bihar | J19: =J18 -> Female | K19: =K18 -> 8821 | ... M19: =M18 -> 5389631
A20: 19 | B20: 46031 | C20: =TEXT(B20,"mmm") -> Jan | D20: Green Leaf Enterprises | E20: Male dress | F20: Fashion | G20: North | H20: Agra | I20: Uttar Pradesh | J20: Male | K20: 9513 | L20: 632 | M20: 6012216
A21: =A20 -> 19 | B21: =B20 -> 46031 | C21: =TEXT(B21,"mmm") -> Jan | D21: Green Leaf Enterprises | E21: =E20 -> Male dress | F21: =F20 -> Fashion | G21: =G20 -> North | H21: =H20 -> Agra | I21: =I20 -> Uttar Pradesh | J21: =J20 -> Male | K21: =K20 -> 9513 | L21: =L20 -> 632 | M21: =M20 -> 6012216
A22: 21 | B22: 45821 | C22: =TEXT(B22,"mmm") -> Jun | D22: Green Leaf Enterprises | E22: TV | F22: Electronic | G22: South | H22: Coimbatore | I22: Tamil Nadu | J22: Male | K22: 4332 | L22: 858 | M22: 3716856
A23: =A22 -> 21 | B23: =B22 -> 45821 | C23: =TEXT(B23,"mmm") -> Jun | D23: =D22 -> Green Leaf Enterprises | E23: =E22 -> TV | F23: =F22 -> Electronic | G23: =G22 -> South | H23: =H22 -> Coimbatore | I23: =I22 -> Tamil Nadu | J23: =J22 -> Male | K23: =K22 -> 4332 | ... M23: =M22 -> 3716856
A24: 23 | B24: 45982 | C24: =TEXT(B24,"mmm") -> Nov | D24: Crystal Clear Solutions | E24: TV | F24: Electronic | G24: North | H24: Jodhpur | I24: Rajasthan | J24: Female | K24: 3691 | L24: 940 | M24: 3469540
A25: =A24 -> 23 | B25: 46078 | C25: =TEXT(B25,"mmm") -> Feb | D25: Modern Trends Fashion | E25: TV | F25: Electronic | G25: North | H25: Varanasi | I25: Uttar Pradesh | J25: Female | K25: 2570 | L25: 704 | M25: 1809280
A26: 25 | B26: 46077 | C26: =TEXT(B26,"mmm") -> Feb | D26: Green Leaf Enterprises | E26: TV | F26: Electronic | G26: South | H26: Kochi | I26: Kerala | J26: Female | K26: 1992 | L26: 538 | M26: 1071696
A27: 26 | B27: 46077 | C27: =TEXT(B27,"mmm") -> Feb | D27: Green Leaf Enterprises | E27: TV | F27: Electronic | G27: West | H27: Aurangabad | I27: Maharashtra | J27: Female | K27: 2907 | L27: 750 | M27: 2180250
A28: 27 | B28: 46031 | C28: =TEXT(B28,"mmm") -> Jan | D28: Future Insights Analytics | E28: TV | F28: Electronic | G28: North | H28: Shimla | I28: Himachal Pradesh | J28: Female | K28: 2936 | L28: 558 | M28: 1638288
A29: =A28 -> 27 | B29: =B28 -> 46031 | C29: =TEXT(B29,"mmm") -> Jan | D29: Future Insights Analytics | E29: =E28 -> TV | F29: =F28 -> Electronic | G29: =G28 -> North | H29: =H28 -> Shimla | I29: =I28 -> Himachal Pradesh | J29: =J28 -> Female | K29: =K28 -> 2936 | L29: =L28 -> 558 | M29: =M28 -> 1638288
A30: 29 | B30: 45986 | C30: =TEXT(B30,"mmm") -> Nov | D30: Future Insights Analytics | E30: TV | F30: Electronic | G30: Central | H30: Raipur | I30: Chhattisgarh | J30: Male | K30: 7291 | L30: 837 | M30: 6102567
A31: 30 | B31: 46003 | C31: =TEXT(B31,"mmm") -> Dec | D31: Future Insights Analytics | E31: TV | F31: Electronic | G31: East | H31: Durgapur | I31: West Bengal | J31: Male | K31: 3141 | L31: 834 | M31: 2619594
A32: 31 | B32: 45898 | C32: =TEXT(B32,"mmm") -> Aug | D32: Golden Era Realty | E32: TV | F32: Electronic | G32: East | H32: Kolkata | I32: West Bengal | J32: Female | K32: 7170 | L32: 521 | M32: 3735570
A33: 32 | B33: 45959 | C33: =TEXT(B33,"mmm") -> Oct | D33: Green Leaf Enterprises | E33: Laptop | F33: Electronic | G33: East | H33: Jamshedpur | I33: Jharkhand | J33: Female | K33: 5398 | L33: 832 | M33: 4491136
A34: 33 | B34: 45977 | C34: =TEXT(B34,"mmm") -> Nov | D34: Future Insights Analytics | E34: Laptop | F34: Electronic | G34: East | H34: Siliguri | I34: West Bengal | J34: Female | K34: 9466 | L34: 933 | M34: 8831778
A35: 34 | B35: 46028 | C35: =TEXT(B35,"mmm") -> Jan | D35: Future Insights Analytics | E35: Laptop | F35: Electronic | G35: South | H35: Mangalore | I35: Karnataka | J35: Female | K35: 4168 | L35: 769 | M35: 3205192
A36: 35 | B36: 46001 | C36: =TEXT(B36,"mmm") -> Dec | D36: Urban Edge Consulting | E36: Laptop | F36: Electronic | G36: North | H36: Delhi | I36: Delhi | J36: Female | K36: 5773 | L36: 627 | M36: 3619671
A37: =A36 -> 35 | B37: =B36 -> 46001 | C37: =TEXT(B37,"mmm") -> Dec | D37: Green Leaf Enterprises | E37: =E36 -> Laptop | F37: =F36 -> Electronic | G37: =G36 -> North | H37: =H36 -> Delhi | I37: =I36 -> Delhi | J37: =J36 -> Female | K37: =K36 -> 5773 | L37: =L36 -> 627 | M37: =M36 -> 3619671
A38: 37 | B38: 45762 | C38: =TEXT(B38,"mmm") -> Apr | D38: Green Leaf Enterprises | E38: Laptop | F38: Electronic | G38: East | H38: Kolkata | I38: West Bengal | J38: Female | K38: 4691 | L38: 901 | M38: 4226591
A39: 38 | B39: 45773 | C39: =TEXT(B39,"mmm") -> Apr | D39: Green Leaf Enterprises | E39: Laptop | F39: Electronic | G39: South | H39: Chennai | I39: Tamil Nadu | J39: Female | K39: 5945 | L39: 887 | M39: 5273215
A40: 39 | B40: 46064 | C40: =TEXT(B40,"mmm") -> Feb | D40: Green Leaf Enterprises | E40: Laptop | F40: Electronic | G40: South | H40: Bengaluru | I40: Karnataka | J40: Female | K40: 6807 | L40: 607 | M40: 4131849
...

Sheet Sumifs
A1: Party Name | B1: Apr | C1: May | D1: Jun | E1: Jul | F1: Aug | G1: Sep | H1: Oct | I1: Nov | J1: Dec | K1: Jan | L1: Feb | M1: Mar | N1: Total
A2: Bharat Innovations | B2: {=SUMIFS('Master data'!$M$2:$M$295,'Master data'!$D$2:$D$295,A2:A148,'Master data'!$C$2:$C$295,B1:M1)} -> 0 | C2: 0 | D2: 0 | E2: 0 | F2: 0 | G2: 0 | H2: 0 | I2: 0 | J2: 0 | K2: 0 | L2: 3360636 | M2: 0 | N2: =SUM(B2:M2) -> 3360636
A3: Green Leaf Enterprises | B3: 9499806 | C3: 17420760 | D3: 7433712 | E3: 0 | F3: 0 | G3: 0 | H3: 4491136 | I3: 5512404 | J3: 9439416 | K3: 19568818 | L3: 16662614 | M3: 0 | N3: =SUM(B3:M3) -> 90028666
A4: Mystic India Exports | B4: 0 | C4: 0 | D4: 0 | E4: 0 | F4: 0 | G4: 0 | H4: 0 | I4: 0 | J4: 0 | K4: 3566605 | L4: 0 | M4: 0 | N4: =SUM(B4:M4) -> 3566605
A5: Zenith Construction Co. | B5: 0 | C5: 0 | D5: 0 | E5: 0 | F5: 0 | G5: 1657096 | H5: 0 | I5: 0 | J5: 0 | K5: 0 | L5: 0 | M5: 0 | N5: =SUM(B5:M5) -> 1657096
A6: Divine Creations | B6: 0 | C6: 0 | D6: 0 | E6: 0 | F6: 0 | G6: 0 | H6: 0 | I6: 0 | J6: 0 | K6: 0 | L6: 3443532 | M6: 0 | N6: =SUM(B6:M6) -> 3443532
A7: Metro Tech Solutions | B7: 0 | C7: 0 | D7: 3577658 | E7: 0 | F7: 0 | G7: 0 | H7: 0 | I7: 0 | J7: 0 | K7: 0 | L7: 0 | M7: 0 | N7: =SUM(B7:M7) -> 3577658
A8: True Path Logistics | B8: 0 | C8: 0 | D8: 0 | E8: 0 | F8: 0 | G8: 0 | H8: 1276242 | I8: 0 | J8: 0 | K8: 0 | L8: 0 | M8: 0 | N8: =SUM(B8:M8) -> 1276242
A9: Visionary Holdings | B9: 0 | C9: 0 | D9: 0 | E9: 0 | F9: 0 | G9: 0 | H9: 0 | I9: 0 | J9: 0 | K9: 4510462 | L9: 0 | M9: 0 | N9: =SUM(B9:M9) -> 4510462
A10: Stellar Design Studio | B10: 0 | C10: 0 | D10: 0 | E10: 10779262 | F10: 0 | G10: 0 | H10: 0 | I10: 0 | J10: 0 | K10: 0 | L10: 0 | M10: 0 | N10: =SUM(B10:M10) -> 10779262
A11: Crystal Clear Solutions | B11: 0 | C11: 0 | D11: 0 | E11: 0 | F11: 0 | G11: 0 | H11: 0 | I11: 3469540 | J11: 0 | K11: 0 | L11: 0 | M11: 0 | N11: =SUM(B11:M11) -> 3469540
A12: Modern Trends Fashion | B12: 0 | C12: 0 | D12: 0 | E12: 0 | F12: 0 | G12: 0 | H12: 0 | I12: 0 | J12: 0 | K12: 0 | L12: 1809280 | M12: 0 | N12: =SUM(B12:M12) -> 1809280
A13: Future Insights Analytics | B13: 24171699 | C13: 0 | D13: 17642676 | E13: 18771986 | F13: 18251892 | G13: 10762649 | H13: 4605916 | I13: 25097581 | J13: 10357596 | K13: 15032265 | L13: 11536096 | M13: 0 | N13: =SUM(B13:M13) -> 156230356
A14: Golden Era Realty | B14: 0 | C14: 0 | D14: 0 | E14: 0 | F14: 3735570 | G14: 0 | H14: 0 | I14: 0 | J14: 0 | K14: 0 | L14: 0 | M14: 0 | N14: =SUM(B14:M14) -> 3735570
... A148: Legacy Health Co. | B148: 0 | C148: 0 | D148: 3425638 | E148: 0 | F148: 0 | G148: 0 | H148: 0 | I148: 0 | J148: 0 | K148: 0 | L148: 0 | M148: 0 | N148: =SUM(B148:M148) -> 3425638
A156: Party Name | B156: Apr | C156: May | D156: Jun | E156: Jul | F156: Aug | G156: Sep | H156: Oct | I156: Nov | J156: Dec | K156: Jan | L156: Feb | M156: Mar | N156: Total
A157: Bharat Innovations | B157: - | C157: - | D157: - | E157: - | F157: - | G157: - | H157: - | I157: - | J157: - | K157: - | L157: 3360636 | M157: - | N157: =AVERAGE(B157:M157) -> 3360636
