Workbook
Name Slicer_Category: #N/A
Name Slicer_Gender: #N/A
Name Slicer_OrderChannel: #N/A
Name Slicer_Region: #N/A
Name Timeline_OrderDate: #N/A

Sheet Monthly Report
B2: 📊 MONTHLY SALES DASHBOARD
B3: April 2025 – April 2026 | All Data
B5: TOTAL REVENUE | E5: TOTAL ORDERS | H5: AVG RATING | K5: AVG DELIVERY DAYS
B6: =SUM('[1]Main Data'!Q2:Q1001) -> 80659661 | E6: =COUNTA('[1]Main Data'!A2:A1001) -> 1000 | H6: =AVERAGE('[1]Main Data'!Y2:Y1001) -> 3.002 | K6: =AVERAGE('[1]Main Data'!W2:W1001) -> 5.463

Sheet Pivot
A3: Row Labels | B3: Sum of TotalAmount
A4: Electronics | B4: 57012219
A5: Accessories | B5: 6917057.3
A6: Fashion | B6: 16804488
A7: (blank)
A8: Grand Total | B8: 80733764
A54: Instagram | B54: 1000000
A55: Website | B55: 500000
A56: Cart | B56: 100000
A57: Purchase | B57: 50000
A73: Category | B73: product | C73: amount
A74: A | B74: A1 | C74: 27873
A75: B | B75: B1 | C75: 34911
A76: C | B76: C1 | C76: 11939
A77: D | B77: D1 | C77: 16911
A78: A | B78: A2 | C78: 42232
A79: B | B79: B2 | C79: 16656
A80: C | B80: C2 | C80: 16697
A81: D | B81: D2 | C81: 10073
A95: State | B95: Amount
A96: Haryana | B96: =RANDBETWEEN(100000,500000) -> 491959
A97: Rajasthan | B97: =RANDBETWEEN(100000,500000) -> 481967
A98: Maharashtra | B98: =RANDBETWEEN(100000,500000) -> 400601
A99: Andra Pradesh | B99: =RANDBETWEEN(100000,500000) -> 118058
A100: Assam | B100: =RANDBETWEEN(100000,500000) -> 457753
A101: Bihar | B101: =RANDBETWEEN(100000,500000) -> 400739
A102: Uttar Pradesh | B102: =RANDBETWEEN(100000,500000) -> 382551
A103: Gujrat | B103: =RANDBETWEEN(100000,500000) -> 481447

Sheet Main Data
A1: OrderID | B1: OrderDate | C1: CustomerID | D1: CustomerName | E1: Gender | F1: Age | G1: Product | H1: Category | I1: SubCategory | J1: Brand | K1: Quantity | L1: UnitPrice | M1: Discount | N1: DiscountAmount | O1: Tax | P1: ShippingCost | Q1: TotalAmount | R1: PaymentMethod | S1: OrderChannel | T1: City | U1: State | V1: Region | W1: DeliveryDays | X1: ReturnStatus | Y1: Rating | Z1: Status
A2: ORD00001 | B2: 45854 | C2: CUST883 | D2: Rahul | E2: Female | F2: 35 | G2: Headphones | H2: Electronics | I2: Headphones | J2: Sony | K2: 2 | L2: 24446 | M2: 5 | N2: 2444.6 | O2: 8360.53 | P2: 310 | Q2: 55117.93 | R2: Net Banking | S2: Website | T2: Mumbai | U2: Maharashtra | V2: West | W2: 1 | X2: No Return | Y2: 1 | Z2: Delivered
A3: ORD00002 | B3: 45791 | C3: CUST657 | D3: Neha | E3: Male | F3: 45 | G3: Keyboard | H3: Electronics | I3: Keyboard | J3: Sony | K3: 2 | L3: 18047 | M3: 20 | N3: 7218.8 | O3: 5197.54 | P3: 363 | Q3: 34435.74 | R3: Cash on Delivery | S3: Website | T3: Pune | U3: Maharashtra | V3: West | W3: 4 | X3: No Return | Y3: 1 | Z3: Returned
A4: ORD00003 | B4: 45897 | C4: CUST546 | D4: Arjun | E4: Female | F4: 29 | G4: Shoes | H4: Fashion | I4: Shoes | J4: Boat | K4: 2 | L4: 15876 | M4: 5 | N4: 1587.6 | O4: 5429.59 | P4: 156 | Q4: 35749.99 | R4: UPI | S4: Website | T4: Chandigarh | U4: Punjab | V4: North | W4: 3 | X4: No Return | Y4: 4 | Z4: Cancelled
A5: ORD00004 | B5: 45850 | C5: CUST355 | D5: Priya | E5: Female | F5: 18 | G5: Keyboard | H5: Electronics | I5: Keyboard | J5: Dell | K5: 4 | L5: 22930 | M5: 15 | N5: 13758 | O5: 14033.16 | P5: 264 | Q5: 92259.16 | R5: Cash on Delivery | S5: Mobile App | T5: Chandigarh | U5: Punjab | V5: North | W5: 10 | X5: No Return | Y5: 2 | Z5: Delivered
A6: ORD00005 | B6: 45929 | C6: CUST595 | D6: Vikas | E6: Male | F6: 22 | G6: Backpack | H6: Accessories | I6: Backpack | J6: HP | K6: 3 | L6: 28947 | M6: 10 | N6: 8684.1 | O6: 14068.24 | P6: 398 | Q6: 92623.14 | R6: Net Banking | S6: Mobile App | T6: Patiala | U6: Punjab | V6: North | W6: 6 | X6: No Return | Y6: 2 | Z6: Delivered
A7: ORD00006 | B7: 46058 | C7: CUST587 | D7: Sneha | E7: Male | F7: 45 | G7: Laptop | H7: Electronics | I7: Laptop | J7: Lenovo | K7: 5 | L7: 5222 | M7: 10 | N7: 2611 | O7: 4229.82 | P7: 392 | Q7: 28120.82 | R7: Net Banking | S7: Mobile App | T7: Jaipur | U7: Rajasthan | V7: North | W7: 6 | X7: No Return | Y7: 3 | Z7: Delivered
A8: ORD00007 | B8: 46009 | C8: CUST842 | D8: Amit | E8: Female | F8: 42 | G8: Headphones | H8: Electronics | I8: Headphones | J8: Dell | K8: 3 | L8: 47976 | M8: 10 | N8: 14392.8 | O8: 23316.34 | P8: 272 | Q8: 153123.54 | R8: Cash on Delivery | S8: Mobile App | T8: Mumbai | U8: Maharashtra | V8: West | W8: 7 | X8: Returned | Y8: 1 | Z8: Returned
A9: ORD00008 | B9: 45781 | C9: CUST666 | D9: Arjun | E9: Male | F9: 28 | G9: Keyboard | H9: Electronics | I9: Keyboard | J9: HP | K9: 1 | L9: 15216 | M9: 10 | N9: 1521.6 | O9: 2464.99 | P9: 366 | Q9: 16525.39 | R9: Card | S9: Website | T9: Bangalore | U9: Karnataka | V9: South | W9: 3 | X9: No Return | Y9: 4 | Z9: Returned
A10: ORD00009 | B10: 45778 | C10: CUST794 | D10: Karan | E10: Male | F10: 52 | G10: Camera | H10: Electronics | I10: Camera | J10: Lenovo | K10: 3 | L10: 39902 | M10: 0 | N10: 0 | O10: 21547.08 | P10: 82 | Q10: 141335.08 | R10: UPI | S10: Website | T10: Bangalore | U10: Karnataka | V10: South | W10: 8 | X10: No Return | Y10: 4 | Z10: Shipped
A11: ORD00010 | B11: 45863 | C11: CUST126 | D11: Karan | E11: Female | F11: 32 | G11: Phone | H11: Electronics | I11: Phone | J11: Sony | K11: 5 | L11: 20474 | M11: 5 | N11: 5118.5 | O11: 17505.27 | P11: 217 | Q11: 114973.77 | R11: Card | S11: Mobile App | T11: Lucknow | U11: Uttar Pradesh | V11: North | W11: 7 | X11: No Return | Y11: 5 | Z11: Shipped
A12: ORD00011 | B12: 45832 | C12: CUST244 | D12: Amit | E12: Male | F12: 22 | G12: Watch | H12: Fashion | I12: Watch | J12: Dell | K12: 5 | L12: 33495 | M12: 0 | N12: 0 | O12: 30145.5 | P12: 336 | Q12: 197956.5 | R12: Card | S12: Website | T12: Bangalore | U12: Karnataka | V12: South | W12: 10 | X12: No Return | Y12: 4 | Z12: Returned
A13: ORD00012 | B13: 46033 | C13: CUST221 | D13: Arjun | E13: Female | F13: 58 | G13: Headphones | H13: Electronics | I13: Headphones | J13: Samsung | K13: 5 | L13: 28508 | M13: 0 | N13: 0 | O13: 25657.2 | P13: 8 | Q13: 168205.2 | R13: Net Banking | S13: Website | T13: Delhi | U13: Delhi | V13: North | W13: 4 | X13: Returned | Y13: 1 | Z13: Returned
... A1002: ORD01001 | B1002: 46006 | C1002: CUST131 | D1002: Sneha | E1002: Female | F1002: 39 | G1002: Headphones | H1002: Electronics | I1002: USB Cable | J1002: Adidas | K1002: 3 | L1002: 26044 | M1002: 20 | N1002: 15626.4 | O1002: 11251.01 | P1002: 346 | Q1002: 74102.61 | R1002: Net Banking | S1002: Website | T1002: Patiala | U1002: Punjab | V1002: North | W1002: 9 | X1002: Returned | Y1002: 3 | Z1002: Shipped

Sheet Dashboard Data
A1: OrderID | B1: OrderDate | C1: CustomerID | D1: CustomerName | E1: Gender | F1: Age | G1: Product | H1: Category | I1: SubCategory | J1: Brand | K1: Quantity | L1: UnitPrice | M1: Discount | N1: DiscountAmount | O1: Tax | P1: ShippingCost | Q1: TotalAmount | R1: PaymentMethod | S1: OrderChannel | T1: City | U1: State | V1: Region | W1: DeliveryDays | X1: ReturnStatus | Y1: Rating | Z1: Status
A2: ORD00001 | B2: 45854 | C2: CUST883 | D2: Rahul | E2: Female | F2: 35 | G2: Headphones | H2: Electronics | I2: Headphones | J2: Sony | K2: 2 | L2: 24446 | M2: 5 | N2: 2444.6 | O2: 8360.53 | P2: 310 | Q2: 55117.93 | R2: Net Banking | S2: Website | T2: Mumbai | U2: Maharashtra | V2: West | W2: 1 | X2: No Return | Y2: 1 | Z2: Delivered
A3: ORD00002 | B3: 45791 | C3: CUST657 | D3: Neha | E3: Male | F3: 45 | G3: Keyboard | H3: Electronics | I3: Keyboard | J3: Sony | K3: 2 | L3: 18047 | M3: 20 | N3: 7218.8 | O3: 5197.54 | P3: 363 | Q3: 34435.74 | R3: Cash on Delivery | S3: Website | T3: Pune | U3: Maharashtra | V3: West | W3: 4 | X3: No Return | Y3: 1 | Z3: Returned
A4: ORD00003 | B4: 45897 | C4: CUST546 | D4: Arjun | E4: Female | F4: 29 | G4: Shoes | H4: Fashion | I4: Shoes | J4: Boat | K4: 2 | L4: 15876 | M4: 5 | N4: 1587.6 | O4: 5429.59 | P4: 156 | Q4: 35749.99 | R4: UPI | S4: Website | T4: Chandigarh | U4: Punjab | V4: North | W4: 3 | X4: No Return | Y4: 4 | Z4: Cancelled
A5: ORD00004 | B5: 45850 | C5: CUST355 | D5: Priya | E5: Female | F5: 18 | G5: Keyboard | H5: Electronics | I5: Keyboard | J5: Dell | K5: 4 | L5: 22930 | M5: 15 | N5: 13758 | O5: 14033.16 | P5: 264 | Q5: 92259.16 | R5: Cash on Delivery | S5: Mobile App | T5: Chandigarh | U5: Punjab | V5: North | W5: 10 | X5: No Return | Y5: 2 | Z5: Delivered
A6: ORD00005 | B6: 45929 | C6: CUST595 | D6: Vikas | E6: Male | F6: 22 | G6: Backpack | H6: Accessories | I6: Backpack | J6: HP | K6: 3 | L6: 28947 | M6: 10 | N6: 8684.1 | O6: 14068.24 | P6: 398 | Q6: 92623.14 | R6: Net Banking | S6: Mobile App | T6: Patiala | U6: Punjab | V6: North | W6: 6 | X6: No Return | Y6: 2 | Z6: Delivered
A7: ORD00006 | B7: 46058 | C7: CUST587 | D7: Sneha | E7: Male | F7: 45 | G7: Laptop | H7: Electronics | I7: Laptop | J7: Lenovo | K7: 5 | L7: 5222 | M7: 10 | N7: 2611 | O7: 4229.82 | P7: 392 | Q7: 28120.82 | R7: Net Banking | S7: Mobile App | T7: Jaipur | U7: Rajasthan | V7: North | W7: 6 | X7: No Return | Y7: 3 | Z7: Delivered
A8: ORD00007 | B8: 46009 | C8: CUST842 | D8: Amit | E8: Female | F8: 42 | G8: Headphones | H8: Electronics | I8: Headphones | J8: Dell | K8: 3 | L8: 47976 | M8: 10 | N8: 14392.8 | O8: 23316.34 | P8: 272 | Q8: 153123.54 | R8: Cash on Delivery | S8: Mobile App | T8: Mumbai | U8: Maharashtra | V8: West | W8: 7 | X8: Returned | Y8: 1 | Z8: Returned
A9: ORD00008 | B9: 45781 | C9: CUST666 | D9: Arjun | E9: Male | F9: 28 | G9: Keyboard | H9: Electronics | I9: Keyboard | J9: HP | K9: 1 | L9: 15216 | M9: 10 | N9: 1521.6 | O9: 2464.99 | P9: 366 | Q9: 16525.39 | R9: Card | S9: Website | T9: Bangalore | U9: Karnataka | V9: South | W9: 3 | X9: No Return | Y9: 4 | Z9: Returned
A10: ORD00009 | B10: 45778 | C10: CUST794 | D10: Karan | E10: Male | F10: 52 | G10: Camera | H10: Electronics | I10: Camera | J10: Lenovo | K10: 3 | L10: 39902 | M10: 0 | N10: 0 | O10: 21547.08 | P10: 82 | Q10: 141335.08 | R10: UPI | S10: Website | T10: Bangalore | U10: Karnataka | V10: South | W10: 8 | X10: No Return | Y10: 4 | Z10: Shipped
A11: ORD00010 | B11: 45863 | C11: CUST126 | D11: Karan | E11: Female | F11: 32 | G11: Phone | H11: Electronics | I11: Phone | J11: Sony | K11: 5 | L11: 20474 | M11: 5 | N11: 5118.5 | O11: 17505.27 | P11: 217 | Q11: 114973.77 | R11: Card | S11: Mobile App | T11: Lucknow | U11: Uttar Pradesh | V11: North | W11: 7 | X11: No Return | Y11: 5 | Z11: Shipped
A12: ORD00011 | B12: 45832 | C12: CUST244 | D12: Amit | E12: Male | F12: 22 | G12: Watch | H12: Fashion | I12: Watch | J12: Dell | K12: 5 | L12: 33495 | M12: 0 | N12: 0 | O12: 30145.5 | P12: 336 | Q12: 197956.5 | R12: Card | S12: Website | T12: Bangalore | U12: Karnataka | V12: South | W12: 10 | X12: No Return | Y12: 4 | Z12: Returned
A13: ORD00012 | B13: 46033 | C13: CUST221 | D13: Arjun | E13: Female | F13: 58 | G13: Headphones | H13: Electronics | I13: Headphones | J13: Samsung | K13: 5 | L13: 28508 | M13: 0 | N13: 0 | O13: 25657.2 | P13: 8 | Q13: 168205.2 | R13: Net Banking | S13: Website | T13: Delhi | U13: Delhi | V13: North | W13: 4 | X13: Returned | Y13: 1 | Z13: Returned
... A1001: ORD01000 | B1001: 46006 | C1001: CUST131 | D1001: Sneha | E1001: Female | F1001: 39 | G1001: Headphones | H1001: Electronics | I1001: Headphones | J1001: Adidas | K1001: 3 | L1001: 26044 | M1001: 20 | N1001: 15626.4 | O1001: 11251.01 | P1001: 346 | Q1001: 74102.61 | R1001: Net Banking | S1001: Website | T1001: Patiala | U1001: Punjab | V1001: North | W1001: 9 | X1001: Returned | Y1001: 3 | Z1001: Shipped

Sheet Data Check
C2: OrderID
C3: OrderDate
C4: CustomerID
C5: CustomerName
C6: Gender
C7: Age
C8: Product
C9: Category
C10: SubCategory
C11: Brand
C12: Quantity
C13: UnitPrice
... C27: Status

Sheet KPIS
AC2: =AC4 -> 80659661 | AE2: =AE4 -> 5.463 | AG2: =AG4 -> 3.002
A3: Row Labels | B3: Sum of TotalAmount | E3: Row Labels | F3: Sum of TotalAmount | I3: Row Labels | J3: Sum of TotalAmount | M3: Row Labels | N3: Sum of TotalAmount | Q3: Row Labels | R3: Sum of TotalAmount | U3: Row Labels | V3: Sum of TotalAmount | Y3: Row Labels | Z3: Sum of TotalAmount | AC3: Sum of TotalAmount | AE3: Average of DeliveryDays | AG3: Average of Rating
A4: Jan | B4: 0.085644688 | E4: Backpack | F4: 0.085756092 | I4: Adidas | J4: 0.075605541 | M4: Card | N4: 0.23484262 | Q4: Mobile App | R4: 0.50859993 | U4: Delhi | V4: 0.1351793 | Y4: No Return | Z4: 0.50130134 | AC4: 80659661 | AE4: 5.463 | AG4: 3.002
A5: Feb | B5: 0.062402314 | E5: Camera | F5: 0.089874505 | I5: Apple | J5: 0.098825595 | M5: Cash on Delivery | N5: 0.24382528 | Q5: Website | R5: 0.49140007 | U5: Karnataka | V5: 0.12017612 | Y5: Returned | Z5: 0.49869866
A6: Mar | B6: 0.084071149 | E6: Headphones | F6: 0.11734727 | I6: Boat | J6: 0.11045783 | M6: Net Banking | N6: 0.25601058 | Q6: Grand Total | R6: 1 | U6: Maharashtra | V6: 0.2786923 | Y6: Grand Total | Z6: 1
A7: Apr | B7: 0.080622742 | E7: Keyboard | F7: 0.12747846 | I7: Dell | J7: 0.11831345 | M7: UPI | N7: 0.26532153 | U7: Punjab | V7: 0.2321915
A8: May | B8: 0.078644186 | E8: Laptop | F8: 0.09248757 | I8: HP | J8: 0.094789188 | M8: Grand Total | N8: 1 | U8: Rajasthan | V8: 0.10884442
A9: Jun | B9: 0.068126936 | E9: Mouse | F9: 0.10019628 | I9: Lenovo | J9: 0.097033368 | U9: Uttar Pradesh | V9: 0.12491637
A10: Jul | B10: 0.089830499 | E10: Phone | F10: 0.089275024 | I10: Nike | J10: 0.10066247
A11: Aug | B11: 0.088095022 | E11: Shoes | F11: 0.10320518 | I11: Noise | J11: 0.10197751
A12: Sep | B12: 0.089153586 | E12: Tablet | F12: 0.089246608 | I12: Samsung | J12: 0.084144934
A13: Oct | B13: 0.086356433 | E13: Watch | F13: 0.10513301 | I13: Sony | J13: 0.11819011
A14: Nov | B14: 0.082522954 | I14: Grand Total | J14: 1 | U14: Row Labels | V14: Sum of TotalAmount
A15: Dec | B15: 0.10452949 | U15: =IF(U4=0,"",U4) -> Delhi | V15: =IF(V4=0,"",V4) -> 0.1351793
A16: Grand Total | B16: 1 | U16: =IF(U5=0,"",U5) -> Karnataka | V16: =IF(V5=0,"",V5) -> 0.12017612
U17: =IF(U6=0,"",U6) -> Maharashtra | V17: =IF(V6=0,"",V6) -> 0.2786923
E18: Row Labels | F18: Sum of TotalAmount | U18: =IF(U7=0,"",U7) -> Punjab | V18: =IF(V7=0,"",V7) -> 0.2321915
E19: =IF(E4=0,"",E4) -> Backpack | F19: =IF(F4=0,"",F4) -> 0.085756092 | U19: =IF(U8=0,"",U8) -> Rajasthan | V19: =IF(V8=0,"",V8) -> 0.10884442
E20: =IF(E5=0,"",E5) -> Camera | F20: =IF(F5=0,"",F5) -> 0.089874505 | U20: =IF(U9=0,"",U9) -> Uttar Pradesh | V20: =IF(V9=0,"",V9) -> 0.12491637
E21: =IF(E6=0,"",E6) -> Headphones | F21: =IF(F6=0,"",F6) -> 0.11734727 | U21: =IF(U10=0,"",U10) | V21: =IF(V10=0,"",V10)
E22: =IF(E7=0,"",E7) -> Keyboard | F22: =IF(F7=0,"",F7) -> 0.12747846
E23: =IF(E8=0,"",E8) -> Laptop | F23: =IF(F8=0,"",F8) -> 0.09248757
E24: =IF(E9=0,"",E9) -> Mouse | F24: =IF(F9=0,"",F9) -> 0.10019628
E25: =IF(E10=0,"",E10) -> Phone | F25: =IF(F10=0,"",F10) -> 0.089275024
E26: =IF(E11=0,"",E11) -> Shoes | F26: =IF(F11=0,"",F11) -> 0.10320518
E27: =IF(E12=0,"",E12) -> Tablet | F27: =IF(F12=0,"",F12) -> 0.089246608
E28: =IF(E13=0,"",E13) -> Watch | F28: =IF(F13=0,"",F13) -> 0.10513301

Sheet Dashboard Creation

Sheet Annual Report
A1: 📊 ANNUAL REPORT
A2: April 2025 – March 2026 | Full Year Performance Summary
A5: 1. EXECUTIVE SUMMARY
B7: Total Revenue | D7: Total Orders | F7: Avg Order Value | H7: Avg Rating | J7: Avg Delivery Days
B8: =SUM('Dashboard Data'!Q2:Q1001) -> 80659661 | D8: =COUNTA('Dashboard Data'!A2:A1001) -> 1000 | F8: =B8/D8 -> 80659.661 | H8: =AVERAGE('Dashboard Data'!Y2:Y1001) -> 3.002 | J8: =AVERAGE('Dashboard Data'!W2:W1001) -> 5.463
A10: 2. MONTHLY REVENUE TREND
A12: Month | B12: Revenue | C12: Orders | D12: Avg Order Value | E12: MoM Growth % | F12: % of Total
A13: 45748 | B13: {=SUMPRODUCT(('Dashboard Data'!Q2:Q1001)*('Dashboard Data'!B2:B1001>=DATE(2025,4,1))*('Dashboard Data'!B2:B1001<DATE(2025,5,1)))} -> 4588151.3 | C13: {=SUMPRODUCT(('Dashboard Data'!B2:B1001>=DATE(2025,4,1))*('Dashboard Data'!B2:B1001<DATE(2025,5,1)))} -> 53 | D13: =IF(C13=0,"-",B13/C13) -> 86568.893 | E13: - | F13: =B13/$B$25 -> 0.05826608
A14: 45778 | B14: {=SUMPRODUCT(('Dashboard Data'!Q2:Q1001)*('Dashboard Data'!B2:B1001>=DATE(2025,5,1))*('Dashboard Data'!B2:B1001<DATE(2025,6,1)))} -> 6343413.4 | C14: {=SUMPRODUCT(('Dashboard Data'!B2:B1001>=DATE(2025,5,1))*('Dashboard Data'!B2:B1001<DATE(2025,6,1)))} -> 88 | D14: =IF(C14=0,"-",B14/C14) -> 72084.243 | E14: - | F14: =B14/$B$25 -> 0.080556591
A15: 45809 | B15: {=SUMPRODUCT(('Dashboard Data'!Q2:Q1001)*('Dashboard Data'!B2:B1001>=DATE(2025,6,1))*('Dashboard Data'!B2:B1001<DATE(2025,7,1)))} -> 5495095.6 | C15: {=SUMPRODUCT(('Dashboard Data'!B2:B1001>=DATE(2025,6,1))*('Dashboard Data'!B2:B1001<DATE(2025,7,1)))} -> 68 | E15: =(B15-B14)/B14 -> -0.13373208 | F15: =B15/$B$25 -> 0.069783591
A16: 45839 | B16: {=SUMPRODUCT(('Dashboard Data'!Q2:Q1001)*('Dashboard Data'!B2:B1001>=DATE(2025,7,1))*('Dashboard Data'!B2:B1001<DATE(2025,8,1)))} -> 7245697.6 | C16: {=SUMPRODUCT(('Dashboard Data'!B2:B1001>=DATE(2025,7,1))*('Dashboard Data'!B2:B1001<DATE(2025,8,1)))} -> 91 | E16: =(B16-B15)/B15 -> 0.31857536 | F16: =B16/$B$25 -> 0.092014923
A17: 45870 | B17: {=SUMPRODUCT(('Dashboard Data'!Q2:Q1001)*('Dashboard Data'!B2:B1001>=DATE(2025,8,1))*('Dashboard Data'!B2:B1001<DATE(2025,9,1)))} -> 7105714.6 | C17: {=SUMPRODUCT(('Dashboard Data'!B2:B1001>=DATE(2025,8,1))*('Dashboard Data'!B2:B1001<DATE(2025,9,1)))} -> 99 | E17: =(B17-B16)/B16 -> -0.019319464 | F17: =B17/$B$25 -> 0.090237244
A18: 45901 | B18: {=SUMPRODUCT(('Dashboard Data'!Q2:Q1001)*('Dashboard Data'!B2:B1001>=DATE(2025,9,1))*('Dashboard Data'!B2:B1001<DATE(2025,10,1)))} -> 7191098.1 | C18: {=SUMPRODUCT(('Dashboard Data'!B2:B1001>=DATE(2025,9,1))*('Dashboard Data'!B2:B1001<DATE(2025,10,1)))} -> 84 | E18: =(B18-B17)/B17 -> 0.012016168 | F18: =B18/$B$25 -> 0.09132155
A19: 45931 | B19: {=SUMPRODUCT(('Dashboard Data'!Q2:Q1001)*('Dashboard Data'!B2:B1001>=DATE(2025,10,1))*('Dashboard Data'!B2:B1001<DATE(2025,11,1)))} -> 6965480.6 | C19: {=SUMPRODUCT(('Dashboard Data'!B2:B1001>=DATE(2025,10,1))*('Dashboard Data'!B2:B1001<DATE(2025,11,1)))} -> 93 | E19: =(B19-B18)/B18 -> -0.031374545 | F19: =B19/$B$25 -> 0.088456378
A20: 45962 | B20: {=SUMPRODUCT(('Dashboard Data'!Q2:Q1001)*('Dashboard Data'!B2:B1001>=DATE(2025,11,1))*('Dashboard Data'!B2:B1001<DATE(2025,12,1)))} -> 6656273.5 | C20: {=SUMPRODUCT(('Dashboard Data'!B2:B1001>=DATE(2025,11,1))*('Dashboard Data'!B2:B1001<DATE(2025,12,1)))} -> 75 | E20: =(B20-B19)/B19 -> -0.044391352 | F20: =B20/$B$25 -> 0.08452968
A21: 45992 | B21: {=SUMPRODUCT(('Dashboard Data'!Q2:Q1001)*('Dashboard Data'!B2:B1001>=DATE(2025,12,1))*('Dashboard Data'!B2:B1001<DATE(2026,1,1)))} -> 8431313.3 | C21: {=SUMPRODUCT(('Dashboard Data'!B2:B1001>=DATE(2025,12,1))*('Dashboard Data'!B2:B1001<DATE(2026,1,1)))} -> 96 | E21: =(B21-B20)/B20 -> 0.2666717 | F21: =B21/$B$25 -> 0.10707135
A22: 46023 | B22: {=SUMPRODUCT(('Dashboard Data'!Q2:Q1001)*('Dashboard Data'!B2:B1001>=DATE(2026,1,1))*('Dashboard Data'!B2:B1001<DATE(2026,2,1)))} -> 6908071.5 | C22: {=SUMPRODUCT(('Dashboard Data'!B2:B1001>=DATE(2026,1,1))*('Dashboard Data'!B2:B1001<DATE(2026,2,1)))} -> 78 | E22: =(B22-B21)/B21 -> -0.18066483 | F22: =B22/$B$25 -> 0.087727326
A23: 46054 | B23: {=SUMPRODUCT(('Dashboard Data'!Q2:Q1001)*('Dashboard Data'!B2:B1001>=DATE(2026,2,1))*('Dashboard Data'!B2:B1001<DATE(2026,3,1)))} -> 5033349.5 | C23: {=SUMPRODUCT(('Dashboard Data'!B2:B1001>=DATE(2026,2,1))*('Dashboard Data'!B2:B1001<DATE(2026,3,1)))} -> 65 | E23: =(B23-B22)/B22 -> -0.27138138 | F23: =B23/$B$25 -> 0.063919763
A24: 46082 | B24: {=SUMPRODUCT(('Dashboard Data'!Q2:Q1001)*('Dashboard Data'!B2:B1001>=DATE(2026,3,1))*('Dashboard Data'!B2:B1001<DATE(2026,4,1)))} -> 6781150.4 | C24: {=SUMPRODUCT(('Dashboard Data'!B2:B1001>=DATE(2026,3,1))*('Dashboard Data'!B2:B1001<DATE(2026,4,1)))} -> 86 | E24: =(B24-B23)/B23 -> 0.34724408 | F24: =B24/$B$25 -> 0.086115522
A25: Total | B25: =SUM(B13:B24) -> 78744809 | C25: =SUM(C13:C24) -> 976
D26: =IF(C26=0,"-",B26/C26) -> - | E26: - | F26: =SUM(F14:F25) -> 0.94173392
A27: 3. REVENUE BY CATEGORY & PRODUCT
A29: Category | B29: Revenue | C29: Orders | D29: % of Revenue | F29: Product | G29: Revenue | H29: Orders | I29: % of Revenue
A30: Electronics | B30: =SUMIFS('Dashboard Data'!Q2:Q1001,'Dashboard Data'!H2:H1001,"Electronics") -> 56938116 | C30: =COUNTIFS('Dashboard Data'!H2:H1001,"Electronics") -> 700 | D30: =B30/$B$33 -> 0.70590572 | F30: Keyboard | G30: =SUMIFS('Dashboard Data'!Q2:Q1001,'Dashboard Data'!G2:G1001,F30) -> 10282369 | H30: =COUNTIFS('Dashboard Data'!G2:G1001,F30) -> 109 | I30: =G30/$G$40 -> 0.12747846
A31: Fashion | B31: =SUMIFS('Dashboard Data'!Q2:Q1001,'Dashboard Data'!H2:H1001,"Fashion") -> 16804488 | C31: =COUNTIFS('Dashboard Data'!H2:H1001,"Fashion") -> 215 | D31: =B31/$B$33 -> 0.20833819 | F31: Headphones | G31: =SUMIFS('Dashboard Data'!Q2:Q1001,'Dashboard Data'!G2:G1001,F31) -> 9465190.9 | H31: =COUNTIFS('Dashboard Data'!G2:G1001,F31) -> 109 | I31: =G31/$G$40 -> 0.11734727 | J31: % of Revenue
A32: Accessories | B32: =SUMIFS('Dashboard Data'!Q2:Q1001,'Dashboard Data'!H2:H1001,"Accessories") -> 6917057.3 | C32: =COUNTIFS('Dashboard Data'!H2:H1001,"Accessories") -> 85 | D32: =B32/$B$33 -> 0.085756092 | F32: Watch | G32: =SUMIFS('Dashboard Data'!Q2:Q1001,'Dashboard Data'!G2:G1001,F32) -> 8479993.2 | H32: =COUNTIFS('Dashboard Data'!G2:G1001,F32) -> 101 | I32: =G32/$G$40 -> 0.10513301 | J32: =H32/$G$40 -> 1.2521749e-06
A33: Total | B33: =SUM(B30:B32) -> 80659661 | C33: =SUM(C30:C32) -> 1000 | D33: =SUM(D30:D32) -> 1 | F33: Shoes | G33: =SUMIFS('Dashboard Data'!Q2:Q1001,'Dashboard Data'!G2:G1001,F33) -> 8324494.7 | H33: =COUNTIFS('Dashboard Data'!G2:G1001,F33) -> 114 | I33: =G33/$G$40 -> 0.10320518
F34: Mouse | G34: =SUMIFS('Dashboard Data'!Q2:Q1001,'Dashboard Data'!G2:G1001,F34) -> 8081798 | H34: =COUNTIFS('Dashboard Data'!G2:G1001,F34) -> 101 | I34: =G34/$G$40 -> 0.10019628
F35: Laptop | G35: =SUMIFS('Dashboard Data'!Q2:Q1001,'Dashboard Data'!G2:G1001,F35) -> 7460016.1 | H35: =COUNTIFS('Dashboard Data'!G2:G1001,F35) -> 101 | I35: =G35/$G$40 -> 0.09248757
F36: Camera | G36: =SUMIFS('Dashboard Data'!Q2:Q1001,'Dashboard Data'!G2:G1001,F36) -> 7249247.1 | H36: =COUNTIFS('Dashboard Data'!G2:G1001,F36) -> 105 | I36: =G36/$G$40 -> 0.089874505
F37: Phone | G37: =SUMIFS('Dashboard Data'!Q2:Q1001,'Dashboard Data'!G2:G1001,F37) -> 7200893.2 | H37: =COUNTIFS('Dashboard Data'!G2:G1001,F37) -> 85 | I37: =G37/$G$40 -> 0.089275024
F38: Tablet | G38: =SUMIFS('Dashboard Data'!Q2:Q1001,'Dashboard Data'!G2:G1001,F38) -> 7198601.2 | H38: =COUNTIFS('Dashboard Data'!G2:G1001,F38) -> 90 | I38: =G38/$G$40 -> 0.089246608
F39: Backpack | G39: =SUMIFS('Dashboard Data'!Q2:Q1001,'Dashboard Data'!G2:G1001,F39) -> 6917057.3 | H39: =COUNTIFS('Dashboard Data'!G2:G1001,F39) -> 85 | I39: =G39/$G$40 -> 0.085756092
F40: Total | G40: =SUM(G30:G39) -> 80659661 | H40: =SUM(H30:H39) -> 1000 | I40: =SUM(I30:I39) -> 1
G41: Backpack
A42: 4. REGIONAL PERFORMANCE | G42: Total | H42: =SUM(H32:H41) -> 1782 | I42: =SUM(I32:I41) -> 1.7551743 | J42: =SUM(J32:J41) -> 1.2521749e-06
A44: Region | B44: Revenue | C44: Orders | D44: % of Revenue | E44: Avg Delivery Days | G44: State | H44: Revenue | I44: Orders | J44: % of Revenue
A45: West | B45: =SUMIFS('Dashboard Data'!Q2:Q1001,'Dashboard Data'!V2:V1001,"West") -> 22479226 | C45: =COUNTIFS('Dashboard Data'!V2:V1001,"West") -> 266 | D45: =B45/$B$48 -> 0.2786923 | E45: =AVERAGEIFS('Dashboard Data'!W2:W1001,'Dashboard Data'!V2:V1001,"West") -> 5.1879699 | G45: Maharashtra | H45: =SUMIFS('Dashboard Data'!Q2:Q1001,'Dashboard Data'!U2:U1001,G45) -> 22479226 | I45: =COUNTIFS('Dashboard Data'!U2:U1001,G45) -> 266 | J45: =H45/SUM($H$45:$H$50) -> 0.2786923
A46: North | B46: =SUMIFS('Dashboard Data'!Q2:Q1001,'Dashboard Data'!V2:V1001,"North") -> 48487070 | C46: =COUNTIFS('Dashboard Data'!V2:V1001,"North") -> 611 | D46: =B46/$B$48 -> 0.60113159 | E46: =AVERAGEIFS('Dashboard Data'!W2:W1001,'Dashboard Data'!V2:V1001,"North") -> 5.5433715 | G46: Punjab | H46: =SUMIFS('Dashboard Data'!Q2:Q1001,'Dashboard Data'!U2:U1001,G46) -> 18728488 | I46: =COUNTIFS('Dashboard Data'!U2:U1001,G46) -> 239 | J46: =H46/SUM($H$45:$H$50) -> 0.2321915
A47: South | B47: =SUMIFS('Dashboard Data'!Q2:Q1001,'Dashboard Data'!V2:V1001,"South") -> 9693364.7 | C47: =COUNTIFS('Dashboard Data'!V2:V1001,"South") -> 123 | D47: =B47/$B$48 -> 0.12017612 | E47: =AVERAGEIFS('Dashboard Data'!W2:W1001,'Dashboard Data'!V2:V1001,"South") -> 5.6585366 | G47: Delhi | H47: =SUMIFS('Dashboard Data'!Q2:Q1001,'Dashboard Data'!U2:U1001,G47) -> 10903517 | I47: =COUNTIFS('Dashboard Data'!U2:U1001,G47) -> 133 | J47: =H47/SUM($H$45:$H$50) -> 0.1351793
...
