Workbook

Sheet Original_Data
A1: Order_ID | B1: Order_Date | C1: Age_Group | D1: City | E1: Product | F1: Quantity | G1: Sales | H1: Cost | I1: Profit | J1: Payment_Mode | K1: Order_Type | L1: Profit_Margin_% | M1: Month
A2: ORD0247 | B2: 2026-01-01 | C2: 45+ | D2: Pune | E2: Coffee | F2: 1 | G2: 81 | H2: 40 | I2: 41 | J2: Card | K2: Dine-in | L2: 50.6 | M2: Jan-2026
A3: ORD0049 | B3: 2026-01-01 | C3: 18-24 | D3: Pune | E3: Coffee | F3: 1 | G3: 90 | H3: 40 | I3: 50 | J3: UPI | K3: Delivery | L3: 55.6 | M3: Jan-2026
A4: ORD0171 | B4: 2026-01-01 | C4: 25-34 | D4: Pune | E4: Coffee | F4: 1 | G4: 90 | H4: 40 | I4: 50 | J4: UPI | K4: Dine-in | L4: 55.6 | M4: Jan-2026
A5: ORD0018 | B5: 2026-01-01 | C5: 25-34 | D5: Pune | E5: Pasta | F5: 1 | G5: 220 | H5: 180 | I5: 40 | J5: UPI | K5: Dine-in | L5: 18.2 | M5: Jan-2026
A6: ORD0230 | B6: 2026-01-02 | C6: 18-24 | D6: Mumbai | E6: Pizza | F6: 1 | G6: 330 | H6: 250 | I6: 80 | J6: Card | K6: Dine-in | L6: 24.2 | M6: Jan-2026
A7: ORD0006 | B7: 2026-01-02 | C7: 35-44 | D7: Mumbai | E7: Pizza | F7: 1 | G7: 300 | H7: 250 | I7: 50 | J7: Card | K7: Delivery | L7: 16.7 | M7: Jan-2026
A8: ORD0022 | B8: 2026-01-02 | C8: 25-34 | D8: Nashik | E8: Pizza | F8: 1 | G8: 300 | H8: 250 | I8: 50 | J8: UPI | K8: Delivery | L8: 16.7 | M8: Jan-2026
A9: ORD0088 | B9: 2026-01-03 | C9: 25-34 | D9: Mumbai | E9: Burger | F9: 1 | G9: 162 | H9: 115 | I9: 47 | J9: UPI | K9: Delivery | L9: 29.0 | M9: Jan-2026
A10: ORD0002 | B10: 2026-01-03 | C10: 25-34 | D10: Mumbai | E10: Pizza | F10: 1 | G10: 300 | H10: 250 | I10: 50 | J10: Cash | K10: Dine-in | L10: 16.7 | M10: Jan-2026
A11: ORD0144 | B11: 2026-01-03 | C11: 45+ | D11: Pune | E11: Pizza | F11: 1 | G11: 300 | H11: 250 | I11: 50 | J11: UPI | K11: Dine-in | L11: 16.7 | M11: Jan-2026
A12: ORD0094 | B12: 2026-01-03 | C12: 45+ | D12: Mumbai | E12: Burger | F12: 2 | G12: 360 | H12: 230 | I12: 130 | J12: Cash | K12: Delivery | L12: 36.1 | M12: Jan-2026
... A251: ORD0044 | B251: 2026-03-31 | C251: 35-44 | D251: Pune | E251: Sandwich | F251: 1 | G251: 154 | H251: 80 | I251: 74 | J251: Card | K251: Dine-in | L251: 48.1 | M251: Mar-2026

Sheet Clean_Data
A1: Order_ID | B1: Order_Date | C1: Age_Group | D1: City | E1: Product | F1: Quantity | G1: Sales | H1: Cost | I1: Profit | J1: Payment_Mode | K1: Order_Type | L1: Profit_Margin_% | M1: Month | N1: Year | O1: Quarter | P1: Month_Name | Q1: Year_Month | R1: Average_Selling_Price | S1: Calculated_Profit_Margin_% | T1: Review_Flag | U1: Review_Reason
A2: ORD0247 | B2: 46023 | C2: 45+ | D2: Pune | E2: Coffee | F2: 1 | G2: 81 | H2: 40 | I2: 41 | J2: Card | K2: Dine-In | L2: 50.6 | M2: Jan-2026 | N2: =IF(B2="","",YEAR(B2)) -> 2026 | O2: =IF(B2="","","Q"&ROUNDUP(MONTH(B2)/3,0)) -> Q1 | P2: =IF(B2="","",TEXT(B2,"mmmm")) -> January | Q2: =IF(B2="","",TEXT(B2,"yyyy-mm")) -> 2026-01 | R2: =IFERROR(G2/F2,"") -> 81 | S2: =IFERROR(I2/G2,"") -> 0.50617284 | T2: OK
A3: ORD0049 | B3: 46023 | C3: 18-24 | D3: Pune | E3: Coffee | F3: 1 | G3: 90 | H3: 40 | I3: 50 | J3: Upi | K3: Delivery | L3: 55.6 | M3: Jan-2026 | N3: =IF(B3="","",YEAR(B3)) -> 2026 | O3: =IF(B3="","","Q"&ROUNDUP(MONTH(B3)/3,0)) -> Q1 | P3: =IF(B3="","",TEXT(B3,"mmmm")) -> January | Q3: =IF(B3="","",TEXT(B3,"yyyy-mm")) -> 2026-01 | R3: =IFERROR(G3/F3,"") -> 90 | S3: =IFERROR(I3/G3,"") -> 0.55555556 | T3: OK
A4: ORD0171 | B4: 46023 | C4: 25-34 | D4: Pune | E4: Coffee | F4: 1 | G4: 90 | H4: 40 | I4: 50 | J4: Upi | K4: Dine-In | L4: 55.6 | M4: Jan-2026 | N4: =IF(B4="","",YEAR(B4)) -> 2026 | O4: =IF(B4="","","Q"&ROUNDUP(MONTH(B4)/3,0)) -> Q1 | P4: =IF(B4="","",TEXT(B4,"mmmm")) -> January | Q4: =IF(B4="","",TEXT(B4,"yyyy-mm")) -> 2026-01 | R4: =IFERROR(G4/F4,"") -> 90 | S4: =IFERROR(I4/G4,"") -> 0.55555556 | T4: OK
A5: ORD0018 | B5: 46023 | C5: 25-34 | D5: Pune | E5: Pasta | F5: 1 | G5: 220 | H5: 180 | I5: 40 | J5: Upi | K5: Dine-In | L5: 18.2 | M5: Jan-2026 | N5: =IF(B5="","",YEAR(B5)) -> 2026 | O5: =IF(B5="","","Q"&ROUNDUP(MONTH(B5)/3,0)) -> Q1 | P5: =IF(B5="","",TEXT(B5,"mmmm")) -> January | Q5: =IF(B5="","",TEXT(B5,"yyyy-mm")) -> 2026-01 | R5: =IFERROR(G5/F5,"") -> 220 | S5: =IFERROR(I5/G5,"") -> 0.18181818 | T5: OK
A6: ORD0230 | B6: 46024 | C6: 18-24 | D6: Mumbai | E6: Pizza | F6: 1 | G6: 330 | H6: 250 | I6: 80 | J6: Card | K6: Dine-In | L6: 24.2 | M6: Jan-2026 | N6: =IF(B6="","",YEAR(B6)) -> 2026 | O6: =IF(B6="","","Q"&ROUNDUP(MONTH(B6)/3,0)) -> Q1 | P6: =IF(B6="","",TEXT(B6,"mmmm")) -> January | Q6: =IF(B6="","",TEXT(B6,"yyyy-mm")) -> 2026-01 | R6: =IFERROR(G6/F6,"") -> 330 | S6: =IFERROR(I6/G6,"") -> 0.24242424 | T6: OK
A7: ORD0006 | B7: 46024 | C7: 35-44 | D7: Mumbai | E7: Pizza | F7: 1 | G7: 300 | H7: 250 | I7: 50 | J7: Card | K7: Delivery | L7: 16.7 | M7: Jan-2026 | N7: =IF(B7="","",YEAR(B7)) -> 2026 | O7: =IF(B7="","","Q"&ROUNDUP(MONTH(B7)/3,0)) -> Q1 | P7: =IF(B7="","",TEXT(B7,"mmmm")) -> January | Q7: =IF(B7="","",TEXT(B7,"yyyy-mm")) -> 2026-01 | R7: =IFERROR(G7/F7,"") -> 300 | S7: =IFERROR(I7/G7,"") -> 0.16666667 | T7: OK
A8: ORD0022 | B8: 46024 | C8: 25-34 | D8: Nashik | E8: Pizza | F8: 1 | G8: 300 | H8: 250 | I8: 50 | J8: Upi | K8: Delivery | L8: 16.7 | M8: Jan-2026 | N8: =IF(B8="","",YEAR(B8)) -> 2026 | O8: =IF(B8="","","Q"&ROUNDUP(MONTH(B8)/3,0)) -> Q1 | P8: =IF(B8="","",TEXT(B8,"mmmm")) -> January | Q8: =IF(B8="","",TEXT(B8,"yyyy-mm")) -> 2026-01 | R8: =IFERROR(G8/F8,"") -> 300 | S8: =IFERROR(I8/G8,"") -> 0.16666667 | T8: OK
A9: ORD0088 | B9: 46025 | C9: 25-34 | D9: Mumbai | E9: Burger | F9: 1 | G9: 162 | H9: 115 | I9: 47 | J9: Upi | K9: Delivery | L9: 29 | M9: Jan-2026 | N9: =IF(B9="","",YEAR(B9)) -> 2026 | O9: =IF(B9="","","Q"&ROUNDUP(MONTH(B9)/3,0)) -> Q1 | P9: =IF(B9="","",TEXT(B9,"mmmm")) -> January | Q9: =IF(B9="","",TEXT(B9,"yyyy-mm")) -> 2026-01 | R9: =IFERROR(G9/F9,"") -> 162 | S9: =IFERROR(I9/G9,"") -> 0.29012346 | T9: OK
A10: ORD0002 | B10: 46025 | C10: 25-34 | D10: Mumbai | E10: Pizza | F10: 1 | G10: 300 | H10: 250 | I10: 50 | J10: Cash | K10: Dine-In | L10: 16.7 | M10: Jan-2026 | N10: =IF(B10="","",YEAR(B10)) -> 2026 | O10: =IF(B10="","","Q"&ROUNDUP(MONTH(B10)/3,0)) -> Q1 | P10: =IF(B10="","",TEXT(B10,"mmmm")) -> January | Q10: =IF(B10="","",TEXT(B10,"yyyy-mm")) -> 2026-01 | R10: =IFERROR(G10/F10,"") -> 300 | S10: =IFERROR(I10/G10,"") -> 0.16666667 | T10: OK
A11: ORD0144 | B11: 46025 | C11: 45+ | D11: Pune | E11: Pizza | F11: 1 | G11: 300 | H11: 250 | I11: 50 | J11: Upi | K11: Dine-In | L11: 16.7 | M11: Jan-2026 | N11: =IF(B11="","",YEAR(B11)) -> 2026 | O11: =IF(B11="","","Q"&ROUNDUP(MONTH(B11)/3,0)) -> Q1 | P11: =IF(B11="","",TEXT(B11,"mmmm")) -> January | Q11: =IF(B11="","",TEXT(B11,"yyyy-mm")) -> 2026-01 | R11: =IFERROR(G11/F11,"") -> 300 | S11: =IFERROR(I11/G11,"") -> 0.16666667 | T11: OK
A12: ORD0094 | B12: 46025 | C12: 45+ | D12: Mumbai | E12: Burger | F12: 2 | G12: 360 | H12: 230 | I12: 130 | J12: Cash | K12: Delivery | L12: 36.1 | M12: Jan-2026 | N12: =IF(B12="","",YEAR(B12)) -> 2026 | O12: =IF(B12="","","Q"&ROUNDUP(MONTH(B12)/3,0)) -> Q1 | P12: =IF(B12="","",TEXT(B12,"mmmm")) -> January | Q12: =IF(B12="","",TEXT(B12,"yyyy-mm")) -> 2026-01 | R12: =IFERROR(G12/F12,"") -> 180 | S12: =IFERROR(I12/G12,"") -> 0.36111111 | T12: OK
A13: ORD0098 | B13: 46025 | C13: 25-34 | D13: Pune | E13: Pasta | F13: 1 | G13: 220 | H13: 180 | I13: 40 | J13: Upi | K13: Dine-In | L13: 18.2 | M13: Jan-2026 | N13: =IF(B13="","",YEAR(B13)) -> 2026 | O13: =IF(B13="","","Q"&ROUNDUP(MONTH(B13)/3,0)) -> Q1 | P13: =IF(B13="","",TEXT(B13,"mmmm")) -> January | Q13: =IF(B13="","",TEXT(B13,"yyyy-mm")) -> 2026-01 | R13: =IFERROR(G13/F13,"") -> 220 | S13: =IFERROR(I13/G13,"") -> 0.18181818 | T13: OK
... A251: ORD0044 | B251: 46112 | C251: 35-44 | D251: Pune | E251: Sandwich | F251: 1 | G251: 154 | H251: 80 | I251: 74 | J251: Card | K251: Dine-In | L251: 48.1 | M251: Mar-2026 | N251: =IF(B251="","",YEAR(B251)) -> 2026 | O251: =IF(B251="","","Q"&ROUNDUP(MONTH(B251)/3,0)) -> Q1 | P251: =IF(B251="","",TEXT(B251,"mmmm")) -> March | Q251: =IF(B251="","",TEXT(B251,"yyyy-mm")) -> 2026-03 | R251: =IFERROR(G251/F251,"") -> 154 | S251: =IFERROR(I251/G251,"") -> 0.48051948 | T251: OK

Sheet KPI_Analysis
A1: Sales KPI Analysis
A2: KPIs use cleaned records only. Figures are formula-driven and do not assume unavailable fields.
A4: KPI Name | B4: Value | C4: Calculation Logic | D4: Required Columns | E4: Remarks
A5: Total Sales | B5: =SUM(Clean_Data!G2:G251) -> 61336 | C5: SUM(Sales) | D5: Sales | E5: Top-line revenue across cleaned records.
A6: Quantity Sold | B6: =SUM(Clean_Data!F2:F251) -> 331 | C6: SUM(Quantity) | D6: Quantity | E6: Total units sold.
A7: Orders | B7: =COUNTA(Clean_Data!A2:A251) -> 250 | C7: COUNT(Order_ID) | D7: Order_ID | E7: Order rows after exact duplicate removal.
A8: Average Order Value | B8: =IFERROR(B5/B7,0) -> 245.344 | C8: Total Sales / Orders | D8: Sales, Order_ID | E8: Average revenue per order.
A9: Total Cost | B9: =SUM(Clean_Data!H2:H251) -> 44125 | C9: SUM(Cost) | D9: Cost | E9: Aggregate cost.
A10: Total Profit | B10: =SUM(Clean_Data!I2:I251) -> 17211 | C10: SUM(Profit) | D10: Profit | E10: Aggregate profit.
A11: Overall Profit Margin % | B11: =IFERROR(B10/B5,0) -> 0.28060193 | C11: Total Profit / Total Sales | D11: Profit, Sales | E11: Weighted overall margin.
A12: Average Selling Price | B12: =IFERROR(B5/B6,0) -> 185.30514 | C12: Total Sales / Quantity Sold | D12: Sales, Quantity | E12: Blended sales per unit.
A13: Original Rows | B13: 250 | C13: COUNTROWS(Original_Data) | D13: All original columns | E13: Quality check baseline.
A14: Cleaned Rows | B14: 250 | C14: COUNTROWS(Clean_Data) | D14: All cleaned columns | E14: After removing exact duplicates only.
A15: Exact Duplicates Removed | B15: 0 | C15: Original Rows - Cleaned Rows | D15: All columns | E15: Only exact duplicate rows were removed.
A16: Rows Flagged for Review | B16: 0 | C16: COUNTIF(Review_Flag,"Review") | D16: Review_Flag | E16: Flagged rows were retained for audit and review.
A20: Monthly Sales Trend
A21: Year_Month | B21: Sales
A22: 2026-01 | B22: =SUMIF(Clean_Data!$Q$2:$Q$251,A22,Clean_Data!$G$2:$G$251) -> 22646
A23: 2026-02 | B23: =SUMIF(Clean_Data!$Q$2:$Q$251,A23,Clean_Data!$G$2:$G$251) -> 16767
A24: 2026-03 | B24: =SUMIF(Clean_Data!$Q$2:$Q$251,A24,Clean_Data!$G$2:$G$251) -> 21923
A28: Sales by Product
A29: Product | B29: Sales
A30: Burger | B30: =SUMIF(Clean_Data!$E$2:$E$251,A30,Clean_Data!$G$2:$G$251) -> 13626
A31: Coffee | B31: =SUMIF(Clean_Data!$E$2:$E$251,A31,Clean_Data!$G$2:$G$251) -> 5778
A32: Pasta | B32: =SUMIF(Clean_Data!$E$2:$E$251,A32,Clean_Data!$G$2:$G$251) -> 13948
A33: Pizza | B33: =SUMIF(Clean_Data!$E$2:$E$251,A33,Clean_Data!$G$2:$G$251) -> 19500
A34: Sandwich | B34: =SUMIF(Clean_Data!$E$2:$E$251,A34,Clean_Data!$G$2:$G$251) -> 8484
A38: Sales by City
A39: City | B39: Sales
A40: Mumbai | B40: =SUMIF(Clean_Data!$D$2:$D$251,A40,Clean_Data!$G$2:$G$251) -> 20623
A41: Nashik | B41: =SUMIF(Clean_Data!$D$2:$D$251,A41,Clean_Data!$G$2:$G$251) -> 11755
A42: Pune | B42: =SUMIF(Clean_Data!$D$2:$D$251,A42,Clean_Data!$G$2:$G$251) -> 28958
A46: Sales by Category
A47: Product | B47: Sales
A48: Burger | B48: =SUMIF(Clean_Data!$E$2:$E$251,A48,Clean_Data!$G$2:$G$251) -> 13626
A49: Coffee | B49: =SUMIF(Clean_Data!$E$2:$E$251,A49,Clean_Data!$G$2:$G$251) -> 5778
A50: Pasta | B50: =SUMIF(Clean_Data!$E$2:$E$251,A50,Clean_Data!$G$2:$G$251) -> 13948
A51: Pizza | B51: =SUMIF(Clean_Data!$E$2:$E$251,A51,Clean_Data!$G$2:$G$251) -> 19500
A52: Sandwich | B52: =SUMIF(Clean_Data!$E$2:$E$251,A52,Clean_Data!$G$2:$G$251) -> 8484
A56: Sales by Age Group
...

Sheet Charts_and_Visuals
A1: Sales Performance Dashboard
A2: Management view based only on Clean_Data and KPI_Analysis. Missing dimensions are explicitly disclosed.
A4: Total Sales | F4: Total Profit | K4: Profit Margin
A5: =KPI_Analysis!B5 -> 61336 | F5: =KPI_Analysis!B10 -> 17211 | K5: =KPI_Analysis!B11 -> 0.28060193
A8: Quantity Sold | F8: Orders | K8: Avg Order Value
A9: =KPI_Analysis!B6 -> 331 | F9: =KPI_Analysis!B7 -> 250 | K9: =KPI_Analysis!B8 -> 245.344
A12: Business Insights | I12: Data availability note Customer, salesperson, and product category fields are not present in the uploaded CSV. Top Customers, Salesperson Sales, and Sales by Category were therefore not fabricated. Available alternatives are City, Age Group, Payment Mode, and Order Type.
A13: • Pizza is the leading product by sales at ₹19,500.
A14: • Pune is the leading city by sales at ₹28,958.
A15: • 2026-01 is the strongest month by sales at ₹22,646.
A16: • Overall profit is ₹17,211 on sales of ₹61,336.
A17: • 0 rows are flagged for review and remain in the cleaned dataset.

Sheet Cleaning_Log
A1: Cleaning Log and Quality Checks
A2: Transparent record of cleaning actions, decisions, affected rows, and business implications.
A4: Quality Check | B4: Result | C4: Remarks
A5: Original Rows | B5: 250 | C5: Rows received in uploaded CSV
A6: Cleaned Rows | B6: 250 | C6: Rows retained after exact duplicate removal
A7: Exact Duplicates Removed | B7: 0 | C7: Removed only complete row matches
A8: Rows Flagged for Review | B8: 0 | C8: Retained in Clean_Data
A9: Chart Sources | B9: Clean_Data and KPI_Analysis | C9: No chart reads from Original_Data
A12: Step | B12: Field/Area | C12: Action Taken | D12: Affected Rows/Items | E12: Remarks
A13: Headers | B13: All headers | C13: Trimmed and standardized headers to Excel-friendly names | D13: 13 | E13: Original headers remain unchanged in Original_Data.
A14: Text values | B14: Text columns | C14: Trimmed whitespace and standardized categorical case | D14: 250 | E14: Supports consistent grouping and charts.
A15: Dates | B15: Order_Date | C15: Converted valid dates to Excel date values | D15: 250 | E15: Invalid dates would be flagged.
A16: Numbers | B16: Quantity, Sales, Cost, Profit, Profit_Margin_% | C16: Converted numeric text to numeric data types | D16: 250 | E16: Invalid numeric values would be flagged.
A17: Duplicates | B17: All source columns | C17: Removed exact duplicate cleaned rows only | D17: 0 | E17: No fuzzy or near-duplicate deletion performed.
A18: Derived fields | B18: Year, Quarter, Month_Name, Year_Month, Average_Selling_Price, Calculated_Profit_Margin_% | C18: Added formula-driven analytical fields | D18: 250 | E18: Derived only because required columns are available.
A19: Validation | B19: Profit and Profit Margin % | C19: Compared Profit with Sales - Cost and margin with Profit / Sales | D19: 0 | E19: Suspicious records retained and flagged.
A20: Availability | B20: Category, Customer, Salesperson | C20: Not available in uploaded data | D20: 0 | E20: Corresponding KPIs/charts were not assumed or fabricated.

Sheet Data_Dictionary
A1: Data Dictionary
A2: Definitions, data types, transformations, KPI usage, and interpretation guidance.
A4: Cleaned Column | B4: Original Name | C4: Data Type | D4: Meaning | E4: Sample Value | F4: Cleaning Applied | G4: KPI Usage | H4: Remarks
A5: Order_ID | B5: Order_ID | C5: Text | D5: Unique order identifier | E5: ORD0247 | F5: Trimmed; standardized/type converted as applicable | G5: KPI / Chart | H5: Source field retained in Clean_Data
A6: Order_Date | B6: Order_Date | C6: Date | D6: Order transaction date | E6: 46023 | F6: Trimmed; standardized/type converted as applicable | G6: KPI / Chart | H6: Source field retained in Clean_Data
A7: Age_Group | B7: Age_Group | C7: Text | D7: Customer age band | E7: 45+ | F7: Trimmed; standardized/type converted as applicable | G7: KPI / Chart | H7: Source field retained in Clean_Data
A8: City | B8: City | C8: Text | D8: Order city | E8: Pune | F8: Trimmed; standardized/type converted as applicable | G8: KPI / Chart | H8: Source field retained in Clean_Data
A9: Product | B9: Product | C9: Text | D9: Product sold | E9: Coffee | F9: Trimmed; standardized/type converted as applicable | G9: KPI / Chart | H9: Source field retained in Clean_Data
A10: Quantity | B10: Quantity | C10: Number | D10: Units sold | E10: 1 | F10: Trimmed; standardized/type converted as applicable | G10: KPI / Chart | H10: Source field retained in Clean_Data
A11: Sales | B11: Sales | C11: Number | D11: Sales revenue | E11: 81 | F11: Trimmed; standardized/type converted as applicable | G11: KPI / Chart | H11: Source field retained in Clean_Data
A12: Cost | B12: Cost | C12: Number | D12: Associated cost | E12: 40 | F12: Trimmed; standardized/type converted as applicable | G12: KPI / Chart | H12: Source field retained in Clean_Data
A13: Profit | B13: Profit | C13: Number | D13: Sales minus cost | E13: 41 | F13: Trimmed; standardized/type converted as applicable | G13: KPI / Chart | H13: Source field retained in Clean_Data
A14: Payment_Mode | B14: Payment_Mode | C14: Text | D14: Payment method | E14: Card | F14: Trimmed; standardized/type converted as applicable | G14: KPI / Chart | H14: Source field retained in Clean_Data
A15: Order_Type | B15: Order_Type | C15: Text | D15: Dine-in or delivery | E15: Dine-In | F15: Trimmed; standardized/type converted as applicable | G15: KPI / Chart | H15: Source field retained in Clean_Data
A16: Profit_Margin_% | B16: Profit_Margin_% | C16: Number | D16: Source-provided profit margin percentage | E16: 50.6 | F16: Trimmed; standardized/type converted as applicable | G16: KPI / Chart | H16: Source field retained in Clean_Data
A17: Month | B17: Month | C17: Text | D17: Source-provided month label | E17: Jan-2026 | F17: Trimmed; standardized/type converted as applicable | G17: Time Analysis | H17: Source field retained in Clean_Data
A18: Year | B18: Derived | C18: Number | D18: Order year | E18: Formula-driven | F18: Derived formula | G18: Time Analysis | H18: Calculated from available cleaned columns
A19: Quarter | B19: Derived | C19: Text | D19: Calendar quarter | E19: Formula-driven | F19: Derived formula | G19: Time Analysis | H19: Calculated from available cleaned columns
A20: Month_Name | B20: Derived | C20: Text | D20: Full month name | E20: Formula-driven | F20: Derived formula | G20: Time Analysis | H20: Calculated from available cleaned columns
A21: Year_Month | B21: Derived | C21: Text | D21: Sortable YYYY-MM period | E21: Formula-driven | F21: Derived formula | G21: KPI / Chart | H21: Calculated from available cleaned columns
A22: Average_Selling_Price | B22: Derived | C22: Number | D22: Sales divided by quantity | E22: Formula-driven | F22: Derived formula | G22: KPI / Chart | H22: Calculated from available cleaned columns
A23: Calculated_Profit_Margin_% | B23: Derived | C23: Number | D23: Profit divided by sales | E23: Formula-driven | F23: Derived formula | G23: KPI / Chart | H23: Calculated from available cleaned columns
A24: Review_Flag | B24: Derived | C24: Text | D24: Quality review status | E24: Formula-driven | F24: Derived formula | G24: Quality Control | H24: Calculated from available cleaned columns
A25: Review_Reason | B25: Derived | C25: Text | D25: Explanation of flagged issue | E25: Formula-driven | F25: Derived formula | G25: Quality Control | H25: Calculated from available cleaned columns
